Workbook

Sheet 6月
A1: 考核维度 | C1: 考核分值 | D1: 考核指标 | E1: 分值 | F1: 指标定义 | G1: 考核细则 | H1: 涉及单位 | I1: 责任主管 | J1: 焦作整体得分 | K1: 修武 | L1: 博爱 | M1: 武陟 | N1: 沁阳 | O1: 孟州 | P1: 温县 | Q1: 山阳 | R1: 解放 | S1: 马村 | T1: 中站
A2: 核心功能（45%） | B2: 网络运营 | C2: 14 | D2: 故障管控（10分） | E2: 10 | F2: （1）故障次数管控（8分） ①指标定义 根据网络规模分地市设定S级故障发生次数管控目标，S1/S2/S3/S4级故障分别按照10次、5次、2次、1次折合故障次数。焦作目标值21。 | G2: （1）故障次数管控（8分） ①计分办法 次数低于管控目标不扣分，高于管控目标，每超出管控目标1次扣0.05分，扣完为止。 ②评价规则及数据来源 该指标按年度考核，数据来源于云网格系统。 （2）S级故障（2分） ①计分办法 a.发生S1级故障，每次扣罚0.1分;发生S2级故障，每次扣罚0.05分，扣完为止。 b.出现因人为操作不当、非割接时段动网、隐患未排查发现、隐患未及时整改引起故障的，乘系数1.2进行扣分。 ②评价规则及数据来源 该指标按年度考核，数据来源于云网格系统。 | H2: 网络部、交付中心、网运中心 | I2: 薛培延 | J2: 9.3 | K2: 9.1 | L2: 9.1 | M2: 9 | N2: 8.7 | O2: 9.3 | P2: 9.1 | Q2: 9.3 | R2: 9.3 | S2: 9.3 | T2: 9.3
D3: 能力提升（2分） | E3: 2 | F3: （1）指标定义 内外部认证：，指从事线路、动力、无线、ip等专业等相关专业维护工作所涉及集团运维工程师、智网工程师、网络创新工程师以及与专业相关的外部认证。 六级人才：是指参与省公司网络线战略人才或技术人员7级工认证 | G3: （2）计分办法 内外部认证占比=内外部认证人员数量/各单位专业人员总数；内部认证目标完成率100%。 ①系统内部认证完成率，每低0.1%，扣1分； ②外部认证占比网络中心、交付考核目标30%，区县分公司考核目标15%，每低0.1%，扣1分； ③六级人才占比=六级人员数量/各单位专业人员总数要求10%以上，每低0.1%，扣1分 ④科创能力认证通过率，以科创岗位族人数为依据，考核目标60%，每低0.1%，扣1分 ⑤战略人才竞聘，各单位每新增或保持年审通过，加0.5分。 （3）评价规则及数据来源， 该指标为年度指标，数据来源省公司通报数据。 | H3: 网络部、交付中心、网运中心 | I3: 薛培延、程亚浦 | J3: 2 | K3: 2 | L3: 2 | M3: 2 | N3: 2 | O3: 2 | P3: 2 | Q3: 2 | R3: 2 | S3: 2 | T3: 2
B4: 网络服务提升 | C4: 14 | D4: 移动网络满意度（5分） | E4: 5 | F4: 1、指标定义 该指标由移动网络满意度、宽带网络满意度、智家工程师满意度三项指标构成。 | G4: 计分办法： （1）若满意度有全部明细能够区分各单位得分，按照省公司计分办法计算得分； （2）否则按照低评用户占比计算得分： ①根据各单位语音及上网具体打分情况计算低分占比情况； ②得分1分的系数为1，2-6分系数为0.5，7-8系数为0.2； ③计算1-8分得分的占比情况后计算最终得分（满分10分）； 1.当占比≤10%；得分=10−0.09×低评用户占比×100； 2.当占比介于10%和20%之间；得分=10−0.11×低评用户占比×100； 3.当占比≥20%；得分=10−0.13×低评用户占比×100； （3）最终移动网络满意度、宽带网络满意度折算为5分、智家工程师满意度折算为4分。 | H4: 网络部、网运中心 | I4: 雷坤 | J4: 2.5 | K4: 2.5 | L4: 2.5 | M4: 2.5 | N4: 2.5 | O4: 2.5 | P4: 2.5 | Q4: 2.5 | R4: 2.5 | S4: 2.5 | T4: 2.5
D5: 宽固网络满意度（5分） | E5: 5 | H5: 网络部、交付中心 | I5: 贾淑楠 | J5: 3.45 | K5: 3.9 | L5: 2.725 | M5: 1.75 | N5: 5 | O5: 3.57 | P5: 2.725 | Q5: 3.9 | R5: 3.9 | S5: 1.75 | T5: 3.9
D6: 智家工程师满意度（4分） | E6: 4 | H6: 网络部、交付中心 | I6: 贾淑楠 | J6: 2.3927273 | K6: 3.12 | L6: 1.4 | M6: 1.4 | N6: 4 | O6: 3.12 | P6: 1.4 | Q6: 3.12 | R6: 4 | S6: 4 | T6: 3.12
B7: 网运成本管控 | C7: 17 | D7: 网络相关成本占收比（9分） | E7: 9 | F7: （1）指标定义 网络相关成本占收比=（网络相关成本÷联网通信及其他业务收入）×100% 网络相关成本占收比预算目标=（网络相关成本预算÷联网通信及其他业务收入预算）×100% 网络相关成本占收比预算完成率=网络相关成本占收比÷网络相关成本占收比预算目标，焦作目标值：15.01% | G7: （2）计分办法 ①网络相关成本占收比预算完成率≤100%，得满分。 ②网络相关成本占收比预算完成率>100%，每超1PP扣本项分数的10%，线性得分。 （3）评价规则及数据来源 该指标按年度考核，数据来源于财务系统全成本报表。 | H7: 网络部、交付中心、网运中心 | I7: 郭超凡 | J7: 9 | K7: 9 | L7: 9 | M7: 9 | N7: 9 | O7: 9 | P7: 9 | Q7: 9 | R7: 9 | S7: 9 | T7: 9
D8: 铁塔差异管控（3分） | E8: 3 | F8: （1）指标定义 该指标由2025年列账差异率、2025年月列账金额波动率、2023年至2025年订单退租及降配证据固化率三项指标构成。 ①2025年列账差异率=1-联通列账金额÷铁塔列账金额× 100%,增量与存量一体化管控。 ②2025年月列账金额波动幅度 =[（当月列账金额 - 上月列账金额）÷上月列账金额]×100%，考核剔除正常波动值 ③2023年至2025年订单退租及降配证据固化率=通过审核的举证材料÷2023 年 1 月 1 日至 2025 年 12 月 31 日期间造成铁塔出账差异的订单退租及降配的举证材料× 100%。 | G8: （2）计分办法 ①2026年列账差异管控≤5%，分值2分。 2026年年度列账差异管控≤5%不扣分，超过5%得0分。 ②单站租赁费≤ 1605元，分值1分。 单站租赁费≤ 1605元%不扣分，每超过 1元扣 0.1 分。 | H8: 网络部、网运中心 | I8: 王宁 | J8: 3 | K8: 3 | L8: 3 | M8: 3 | N8: 3 | O8: 3 | P8: 3 | Q8: 3 | R8: 3 | S8: 3 | T8: 3
D9: 能耗成本（5分） | E9: 5 | F9: （1）指标定义 能耗成本预算完成率=（全成本科目能耗成本实际完成值/能耗成本预算目标值）×100% 能耗成本压降=各单位压降目标完成值 焦作目标值：网络线能耗成本预算目标2739万元，其他能耗成本预算目标503.6万元 能耗成本压降100万 | G9: （2）计分办法 ①能耗成本预算完成率（4分）=网络线能耗成本完成率（3分）+其他能耗成本完成率（1分） ②实际完成值≤预算目标值得满分。 ③实际完成值每超预算目标值1pp扣本项分数的10%，线性扣分，本指标分值扣完为止。 ④各单位实际完成目标压降比例线性得分，线性排名 （3）评价规则及数据来源 各单位实际完成率 | H9: 网络部、网运中心 | I9: 郭超凡 | J9: 5 | K9: 5 | L9: 5 | M9: 5 | N9: 5 | O9: 5 | P9: 5 | Q9: 5 | R9: 5 | S9: 5 | T9: 5
A10: 运营提升 ( 55%) | B10: 网络质量提升专项行动-工匠行动 | C10: 10 | D10: 工匠行动年度得分排名（10分） | E10: 10 | F10: 1、指标定义 该指标指工匠行动年度积分排名。 | G10: （2）计分办法 工匠行动年度积分第1名的市分公司对应得满分10分。 排名2至18名的市分公司，根据其工匠行动年度积分占第一名市分公司积分的比例，同比计算本项分数。 计算公式为：本项分数 = 10 ×（分公司积分 / 第一名分公司积分） （3）评价规则及数据来源 该指标按年度考核，数据来源以省公司统一发布的工匠行动年度积分统计结果为准。 | H10: 网络部、交付中心、网运中心 | I10: 封舒琪 | J10: 10 | K10: 10 | L10: 10 | M10: 10 | N10: 10 | O10: 10 | P10: 10 | Q10: 10 | R10: 10 | S10: 10 | T10: 10
B11: 网络质量提升专项行动-极简网络 | C11: 10 | D11: 极简网络年度综合评价（10分） | E11: 10 | F11: 1、指标定义 该指标由持续建强基础架构、常态化推进接入段光缆优化整治、提升整体运营能力三项指标构成。 （1）持续建强基础架构=2026年计划完成全量锚点机房实现网络天眼八大能力+锚点机房油机新建13台； （2）常态化推进接入段光缆优化整治=投资307万，按照各单位序时任务分解完成序时进度。 （3）提升整体运营能力=完成103个架构节点机房数字化建模+284机房数字化验收。 | G11: 2、计分办法 （1）持续建强基础架构年底前完成100%，得2.9分，每低于1pp扣基本分*1%，扣完本项分值为止。 （2）常态化推进接入段光缆优化整治月度目标完成100%，得4分，每低于1pp扣基本分*1%，扣完本项分值为止。 （3）提升整体运营能力月度目标完成100%，得3分，每低于1pp扣基本分*1%，扣完本项分值为止 （4）集团公司每采纳极简网络一个案例，对应市公司加0.1分。 （5）极简网络总体得分不超过10分。 | H11: 网络部、交付中心、网运中心 | I11: 程亚浦、方玲珑、戴霜、白阳、王宁 | J11: 10 | K11: 10 | L11: 10 | M11: 10 | N11: 10 | O11: 10 | P11: 10 | Q11: 10 | R11: 10 | S11: 10 | T11: 10
B12: 网络质量提升专项行动-网络运营安全深化年 | C12: 6 | D12: 同路由整治处理（2分） | E12: 2 | F12: 1、指标定义 （1）所有达到S级机房完成纯物理双路由整改（包括同井，同馈窗）； （2）所有上联业务完成不同环路整改。 | G12: 2、计分办法 （1）全量双路由整改年底前完成100%，得50%得分，每低于1pp扣0.2，扣完本项分值为止。 （2）上联业务不同环路整改二季度完成100%，得50%得分，每低于1pp扣0.2，扣完本项分值为止。 | H12: 网络部、交付中心、网运中心 | I12: 戴霜 | J12: 2 | K12: 2 | L12: 2 | M12: 2 | N12: 2 | O12: 2 | P12: 2 | Q12: 2 | R12: 2 | S12: 2 | T12: 2
D13: 网络安全事件（4分） | E13: 4 | F13: （1）指标定义 该指标由账号管理安全事件、违规动网操作、违规数据配置、违规分光事件四项指标构成。 | G13: （2）计分办法 ①发生账号管理安全事件扣1分，最多扣1分。 ②发现一起违规动网操作扣0.2分，因违规动网操作导致发生较大及以上网络故障或网络安全责任事件扣1分，最多扣1分。 ③发现一起违规数据配置扣0.2分，因违规数据配置导致发生较大及以上网络故障或网络安全责任事件扣1分，最多扣1分。 ④发生违规分光事件扣1分，因违规分光导致发生较大及以上网络故障或网络安全责任事件扣4分，最多扣4分。 ⑤被上级单位通报的加倍扣分，最多扣4分。 （3）评价规则及数据来源 该指标按年度进行考核，数据来源于上级单位/省公司通报。 | H13: 网络部、交付中心、网运中心 | I13: 薛培延 | J13: 4 | K13: 4 | L13: 4 | M13: 4 | N13: 4 | O13: 4 | P13: 4 | Q13: 4 | R13: 4 | S13: 4 | T13: 4
B14: 网络服务提升专项行动-移网质量提升 | C14: 11 | D14: 重点场景提升（3分） | E14: 3 | F14: （1）指标定义 该指标由非住宅达标率、住宅专项（A类+千户覆盖达标率）、住宅专项（新建住宅覆盖达标率）、地下空间完成情况（上报及时率及地下空间建设目标完成率）四项指标组成。 | G14: （2）计分办法 ①非住宅场景达标100%（1分） 非住宅达标率100%满分，<85%得0分，中间线性记分。 ②A类+千户场景达标率100%（1分） A类+千户移网覆盖达标率100%满分，<85%得0分，中间线性记分。 ③新建住宅场景达标率100%（0.5分） 新建住宅移网覆盖达标率100%满分，<85%得0分，中间线性记分。 ④工信部覆盖达标率100%（0.5分） 工信部覆盖达标率100%满分，<85%得0分，中间线性记分。 区县建设任务得分取自本地市建设任务得分，每月低于当月建设目标值1%，则线性扣分0.1分，扣完为止。 （3）评价规则及数据来源 该指标按年度进行考核，数据来源于集团评估通报及省内自评。 | H14: 网络部、网运中心 | I14: 程亚浦 | J14: 2.57 | K14: 1.88 | L14: 2.86 | M14: 2.8 | N14: 2.91 | O14: 2.16 | P14: 3 | Q14: 2.44 | R14: 2.68 | S14: 2.44 | T14: 2.68
D15: 移网问题栅格改善（3分） | E15: 3 | F15: （1）指标定义 该指标指年度移网问题栅格改善率。 年度移网问题栅格改善率=12期拍照问题栅格改善数/本年12期拍照问题栅格数。 ①移网问题栅格判定标准：逐月对月移网投诉量≥3或移网服请不满≥4的问题栅格拍照，认定移网问题栅格。 ②问题栅格改善标准：移网问题栅格设定1个月的改善期，省分闭环解决网络问题，并保持改善效果；改善期后，如连续2个月投诉量＜3或移网服请不满＜4，视为问题栅格改善。 | G15: （2）计分办法 ①问题栅格改善率达标目标值80%。 ②达标得满分3分，不达标0分。 （3）评价规则及数据来源 该指标按月跟踪通报，以全年累计改善率计算年度得分。数据来源于集团公司客户服务运营平台。 | H15: 网络部、网运中心 | I15: 程亚浦 | J15: 3 | K15: 3 | L15: 3 | M15: 3 | N15: 3 | O15: 0 | P15: 3 | Q15: 3 | R15: 0 | S15: 3 | T15: 0
D16: 业务感知提升（4分） | E16: 4 | F16: （1）指标定义 该指标由语音业务良好体验率、语音业务感知掉话率、4G数据业务卡顿小区比例、5G数据业务卡顿小区比例、同站重复故障比例五项指标构成。 ①语音业务良好体验率=语音业务良好体验次数/语音业务次数 a.语音业务良好体验次数 = 同时满足“接得通”、“接得快”、“听得清”、“不掉话”的业务次数 ，被叫为移动、电信、固网时，语音业务良好体验只需满足“接得通”、“听得清”、“不掉话”； ②语音业务感知掉话率=语音业务感知掉话次数/语音业务次数 针对双方都是联通移网用户的语音通话进行评价。如果二者之间上一次通话时长超过2秒钟，并且上一次通话结束后40秒之内又发起呼叫（上一次通话的主被叫发起呼叫皆可），排除第二次呼叫拒接、运营商测试以及短号码等因素之后，将上一次通话定义为语音业务感知掉话； ③4G数据业务卡顿小区比例=4G数据业务卡顿小区/4G小区总数 ④5G数据业务卡顿小区比例=5G数据业务卡顿小区/5G小区总数 下行时延大于 200ms 概率超过 10%，记为卡顿小区。(电信 800M小区不纳入考核；联通 900M 小区时延大于 200ms 概率超过 20%，记为卡顿小区。) ⑤同站重复故障比例=（当月同站重复故障数量+集码BBU原因造成的重复故障+连续两个月同站重复故障）/当月物理站址故障总量*100%。 | G16: （2）计分办法 ①语音业务良好体验率≥97%（2分） 达标得满分，＜96%得0分，[96%,97%)线性打分。 ②数据业务体验良好率≥97%（2分） 达标得满分，＜96%得0分，[96%,97%)线性打分。 | H16: 网络部、网运中心 | I16: 王宁 | J16: 2.54 | K16: 0.92 | L16: 2.69 | M16: 0.96 | N16: 2.66 | O16: 2.16 | P16: 2.5 | Q16: 3.42 | R16: 3.3 | S16: 2.48 | T16: 2.22
D17: 移网资源利用率（1分） | E17: 1 | F17: （1）指标定义 该指标指综合考虑3.5GHz、2.1GHz、900M无线资源利用率情况，并基于各频段下行频率资源和小区数进行加权统计。 ①移动资源利用率=[7*3.5GHz宏站小区规模*3.5GHz宏站小区无线资源利用率+2*2.1GHz（20M带宽）宏站小区规模*2.1GHz（20M带宽）宏站小区无线资源利用率+4*2.1GHz（40M带宽）宏站小区规模*2.1GHz（40M带宽）宏站小区无线资源利用率+900MHz宏站小区规模*900MHz宏站小区资源利用率]/(7*3.5GHz宏站小区规模+2*2.1GHz（20M带宽）宏站小区规模+4*2.1GHz（40M带宽）宏站小区规模+900MHz宏站小区规模)。 ②5G中频宏站小区无线资源利用率=Σ(小区自忙时下行PDSCH信道占用PRB个数*相应PRB调用层数）/Σ(小区自忙时的每空分流下行PDSCH信道可用PRB个数*小区下行时域平均最大调度层数(剔除0值))/K值，其中5G中频包括3.5GHz、2.1GHz（20M带宽）、2.1GHz（40M带宽），Σ表示所有5G中频宏站按小区求和，K值取典型值50%。 ③900MHz宏站小区资源利用率=（L900下行PRB占用数/L900下行PRB可用数）*L900小区数量占比+（NR900下行PRB占用数/NR900下行PRB可用数）*NR900小区数量占比。 | G17: （2）计分办法 目标无线资源利用率≥30%。 ①完成值大于等于达标值得满分； ②完成值低于基准值（2026年1月指标）不得分； ③完成值相较于2026年1月基准值未提升，得满分的80%； ④完成值低于达标值，但实现提升的，按照完成情况在满分与满分的80%之间线性计分。 （3）评价规则及数据来源 该指标按年度进行考核，数据来源于集团通报。 | H17: 网络部、网运中心 | I17: 王宁 | J17: 1 | K17: 0.8 | L17: 1 | M17: 1 | N17: 1 | O17: 1 | P17: 1 | Q17: 1 | R17: 1 | S17: 0.8 | T17: 1
B18: 网络服务提升专项行动-智家网络服务提升 | C18: 13 | D18: 交付质量提升（4分） | E18: 4 | F18: （1）指标定义 该指标由装维动作合格率、456标准修障达标率两项指标构成。 ①装维动作合格率=1-不满足装维要求的装维动作总量/装维总量 ②456标准修障达标率=（16点前生单且在456时限内修复的工单数+16点后生单且在第二天12:00前修复的工单数）/（本周期内的竣工单+所选周期结束时间的在途工单） | G18: （2）计分办法 ①各项设定达标值和基准值，高于达标值得满分、低于基准值不得分，在达标值和基准值之间的线性计分。 ②装维动作合格率（2分），达标值≥98.5%，基准值≥95%。 ③456标准修障达标率（2分），达标值≥80%，基准值≥70%。 a.若修机当日好≥90%，456标准修障达标率评价值取实际完成值； b.若修机当日好＜90%，456标准修障达标率评价值=456标准修障达标率实际完成值*修机当日好率。 （3）评价规则及数据来源 该指标按月评价计分，以月指标得分的均值计算年度得分。数据来源于宽带网络数字化运营平台、经营分析系统。 | H18: 网络部、交付中心 | I18: 贾淑楠 | J18: 3.1371429 | K18: 3.1948052 | L18: 3.3216342 | M18: 2 | N18: 4 | O18: 2.9618574 | P18: 4 | Q18: 2.5507178 | R18: 3.6257421 | S18: 2.4106597 | T18: 2
D19: 宽带资源效能提升（3分） | E19: 3 | F19: （1）指标定义 该指标由全量宽带端口利用率、存量资源准确率、新装宽带一次核配准确率三项指标构成。 ①全量宽带端口利用率=所有接入方式下宽带占用端口数/（FTTH端口总量+PON_LAN数据端口总量）。 ②新增号线资源规范率=四项标准都通过的新增末梢分光器/全量的新增末梢分光器 ③新装宽带一次核配准确率=一次性完成资源核配并成功施工报竣的装移机工单数量/新装宽带工单总量*100％。 | G19: （2）计分办法 各项设定基准值和达标值，高于达标值得满分、低于基准值不得分，在达标值和基准值之间的线性计分。 ①全量宽带端口利用率（1分），分地市确定设置基准值、达标值。各地市目标如下：57.92%。 完成值≥达标值得1分；完成值低于基准值得0.8分；完成值低于达标值，但高于基准值的，按照提升值在1分与0.8分之间线性计分。 ②新增号线资源规范率（1分）、新装宽带一次核配准确率（1分），基准值为≥82%，达标值为≥92%。 a.完成值≥92%得1分，完成值＜82%不得分，82%-92%之间线性打分。 b.新装宽带一次核配准确率具备打分条件之前，按照存量资源准确率打分；具备打分条件之后，按照两个子指标分别打分。 （3）评价规则及数据来源 ①全量宽带端口利用率取12月数据进行评价； ②新增号线资源规范率Q1≥70%；Q2≥90%；Q3≥95%；Q4≥95%,未完成序时进度扣1分 ③数据来源于号线资源分析系统、宽带网络数字化运营平台。 | H19: 网络部、交付中心、网运中心 | I19: 贾淑楠 | J19: 3 | K19: 3 | L19: 3 | M19: 3 | N19: 3 | O19: 3 | P19: 3 | Q19: 3 | R19: 3 | S19: 3 | T19: 3
D20: 客户感知提升（6分） | E20: 3 | F20: （1）指标定义 该指标由PON口在服率、PON口质差率、全量宽带故障率（10010+96480）、宽带投诉率、网络服务感知综合评价四项指标构成。 其中网络服务综合感知评价=响应率*10%+解决率*40%+满意率*50%，包括投诉、故障和咨办工单。 | G20: （2）计分办法 ①各项设定达标值和基准值，高于达标值得满分、低于基准值不得分，在达标值和基准值之间的线性计分。 ②PON口在服率（1分），达标值≥99.5%，基准值≥99%。若当月出现规模故障，按次评价，每发生一次当月扣0.5分。 ③PON口质差率（2分），达标值≤2.0%，基准值≤2.24%。若当月出现规模故障，按次评价，每发生一次当月扣0.5分。 （3）评价规则及数据来源 该指标按月评价计分，以月度得分均值计算年度得分。数据来源于宽带网络数字化运营平台、中国联通客服运营平台、经营分析系统。 | H20: 网络部、网运中心 | I20: 薛培延 | J20: 3 | K20: 3 | L20: 3 | M20: 3 | N20: 3 | O20: 3 | P20: 3 | Q20: 3 | R20: 3 | S20: 3 | T20: 3
E21: 3 | G21: （2）计分办法 ①各项设定达标值和基准值，高于达标值得满分、低于基准值不得分，在达标值和基准值之间的线性计分。 ③全量宽带故障率（1分），达标值≤90件/万户，基准值≤110件/万户。 ④宽带投诉率（1分），达标值≤1.3件/万户，基准值≤4件/万户。 ⑤网络服务综合感知评价（1分），达标值≥95%，基准值≥92%。 a.若96480服务满意率≥95%，网络服务综合感知评价取实际完成值； b.若96480服务满意率＜95%，网络服务综合感知评价=网络服务综合感知评价实际完成值*96480服务满意率。 （3）评价规则及数据来源 该指标按月评价计分，以月度得分均值计算年度得分。数据来源于宽带网络数字化运营平台、中国联通客服运营平台、经营分析系统。 | H21: 网络部、交付中心 | I21: 贾淑楠 | J21: 3 | K21: 2.791236 | L21: 3 | M21: 2.9167634 | N21: 3 | O21: 2.6568151 | P21: 3 | Q21: 3 | R21: 2.5923408 | S21: 2.8469195 | T21: 2.542211
B22: 网络服务提升专项行动-政企双线网络服务提升 | C22: 5 | D22: 政企双线交付及时率（1分） | E22: 1 | F22: （1）指标定义 该指标由全量宽带端口利用率、社会地址住宅小区全里末梢分光器准确率、新装宽带一次核配准确率三项、指标构成。 ①全量宽带端口利用率=所有接入方式下宽带占用端口数/（FTTH端口总量+PON_LAN数据端口总量）。 ②新装宽带一次核配准确率=一次性完成资源核配并成功施工报竣的装移机工单数量/新装宽带工单总量*100％。 | G22: （2）计分办法 各项设定基准值和达标值，高于达标值得满分、低于基准值不得分，在达标值和基准值之间的线性计分。 ①全量宽带端口利用率（1分），分地市确定设置基准值、达标值。各地市目标如下：57.92%。 完成值≥达标值得1分；完成值低于基准值得0.8分；完成值低于达标值，但高于基准值的，按照提升值在1分与0.8分之间线性计分。 ②社会地址住宅小区全里末梢分光器准确率：4月之后保持成功率≥92%，每低目标值1个百分点，减0.5分 b.新装宽带一次核配准确率具备打分条件之前，按照存量资源准确率打分；具备打分条件之后，按照两个子指标分别打分。 （3）评价规则及数据来源 ①全量宽带端口利用率取12月数据进行评价； ②新增号线资源规范率Q1≥70%；Q2≥90%；Q3≥95%；Q4≥95%,未完成序时进度扣1分 ③数据来源于号线资源分析系统、宽带网络数字化运营平台。 | H22: 网络部、交付中心 | I22: 方玲珑 | J22: 1 | K22: 1 | L22: 1 | M22: 1 | N22: 1 | O22: 1 | P22: 1 | Q22: 1 | R22: 1 | S22: 1 | T22: 1
D23: 政企双线故障管控（2分） | E23: 2 | F23: （1）指标定义 该指标由政企双线故障4小时处理及时率、政企双线监控告警返单及时率两项指标构成。 | G23: （2）计分办法 ①政企双线故障4小时处理及时率=1-（不及时处理政企双线故障次数÷应处理政企双线故障总次数）×100%，满分1分，基本分0.8分，低于98%不得分，98%-100%之间线性得分，线性部分得分=0.2*（完成值-98%）/(100%-98%)； ②政企双线监控告警返单及时率=1-处理超时的政企双线告警工单数/政企双线告警工单总数，满分1分； （3）评价规则及数据来源 该指标按月评价计分，以月度得分均值计算年度得分。数据来源于OSS2.0业务故障2.0、智慧派单系统。 | H23: 网络部、交付中心 | I23: 方玲珑 | J23: 2 | K23: 2 | L23: 2 | M23: 2 | N23: 2 | O23: 2 | P23: 2 | Q23: 2 | R23: 2 | S23: 2 | T23: 2
D24: 政企双线资源治理（2分） | E24: 2 | F24: （1）指标定义 该指标由政企双线电路拼接、政企双线末端光设施绑定标准地址完整率、B-O-O数据一致性稽核、资源一次自动核配成功率、互联网专线自动开通成功率构成。 互联网专线自动开通成功率=全程自动核配成功率*数据自动制作成功率 | G24: （2）计分办法 ①政企电路拼接完成率：4月之后保持成功率≥98.5%，每低目标值1个百分点，减0.5分 ②政企双线末端光设施绑定标准地址完整率=绑定的政企电路数/全量政企电路数，4月之后保持成功率≥98.5%，每低目标值1个百分点，减0.5分 ③ 双线BOO数据一致率=BO数据一致率*0.4+OO数据一致率*0.6 1、BO数据一致率=BO数量一致率*0.3+BO状态一致率*0.3+BO速率一致率*0.3+BO类型一致率*0.1 注：“BO数量、状态、速率、类型一致率”指B域系统与O域网络资源系统数据稽核一致率。 2、OO数据一致率=OO数量一致率*0.4+OO状态一致率*0.3+OO速率一致率*0.3。目标值96%，完成目标得满分，每低目标值1个百分点，减0.3分. ④资源一次自动核配成功率：4月≥10%；5月≥20%；6月≥30%；7月≥40%；8月≥50%；9月≥60%；10月≥70%；11月以后≥80%，每低目标值1个百分点，减0.3分 ⑤互联网专线自动开通成功率 4月-6月基准值20%、达标值30%，≥30%得满分，<20%不得分，中间线性得分 7月-9月基准值30%、达标值60%，≥60%得满分，<30%不得分，中间线性得分 10月-12月基准值60%、达标值90%，≥90%得满分，<60%不得分，中间线性得分 （3）评价规则及数据来源 该指标按月评价计分，以月度得分均值计算年度得分。数据来源于网络资源中心、B域客户订单、O域网络资源中心和O域网管系统、云网格系统。 | H24: 网络部、交付中心 | I24: 方玲珑 | J24: 2 | K24: 2 | L24: 2 | M24: 2 | N24: 2 | O24: 2 | P24: 2 | Q24: 2 | R24: 2 | S24: 2 | T24: 2
A25: 端网业协同 | B25: 端网业协同 | C25: 10 | D25: 5G登网率 | E25: 3 | F25: （1）指标定义 5G签约用户5G终端登网 | G25: （2）计分办法 月度清单制推进5G终端SA开关打开，按月度目标完成率在60%到100%间线性得分，低于60%不得分 | H25: 网络部、网运中心 | I25: 雷坤 | J25: / | K25: / | L25: / | M25: / | N25: / | O25: / | P25: / | Q25: / | R25: / | S25: / | T25: /
D26: 千兆化 | E26: 7 | F26: （1）指标定义 该指标由路由器压降目标完成率、低速通道整治完成率、终端匹配套餐升级整治完成率组成构成。 | G26: （2）计分办法 按时序进度完成率进行考核，达标不扣分，不达标线性扣分。 | H26: 网络部、交付中心 | I26: 贾淑楠 | J26: 7 | K26: =(80.81-80)/20*7 -> 0.2835 | L26: 7 | M26: =(86.92-80)/20*7 -> 2.422 | N26: 7 | O26: =(95.87-80)/20*7 -> 5.5545 | P26: 7 | Q26: 7 | R26: 7 | S26: 7 | T26: 7
A27: 公司KPI保障 | B27: 公司KPI保障 | C27: -3 | D27: 科技创新（2分） | E27: 2 | F27: （1）指标定义 科技创新研发投入贡献 | G27: ①科技创新研发项目无项目扣1分 ②每月工时未及时录入扣1分 | H27: 网络部、交付中心、网运中心 | I27: 程亚浦 | J27: 2 | K27: 0 | L27: 0 | M27: 0 | N27: 0 | O27: 0 | P27: 0 | Q27: 0 | R27: 0 | S27: 0 | T27: 0
D28: 反诈治理 | E28: -5 | F28: (1)指标定义 该指标由涉案号码治理、政企业务涉案治理、信安工单综合评价率、“内鬼”事件四项指标组成。 | G28: （2）计分方法 指标A:涉案号码治理(1.5分)：1、A1涉案电话号码（含手机号码和固话号码）数量同比下降，得0.5分，同比上升60%得0分，在此之间线性得分。2、当地行业移动电话号码涉案占比偏差率（简称“A2”）：A2≤0.9得1分，A2>1.5不得分，在此之间线性计分。 指标B:政企业务涉案治理（2分）：行业短信端口年度涉案量≤15，得1分；政企固话业务年度涉案量≤2，得1分，或涉案量系统内占比低于用户数占比得1分，高于10个百分点得0分，在此之间线性得分。 指标C：信安工单综合评价率（1分）：2026年信安工单综合评价率全年月均达到92.6%及以上的，得1分；90%-92.6%线性得分，低于90%不得分； 指标D：“内鬼”事件（0.5分） 市场发展、业务合作、IT支撑、渠道管理、网络运营及建设等领域，2026年没有新发生的“内鬼”事件，得满分；发生内鬼事件，视情况扣0.2-0.5分。 | H28: 网络部、交付中心、网运中心 | I28: 封舒琪 | J28: -1.2 | K28: 0 | L28: 0 | M28: -0.8 | N28: 0 | O28: -1.3 | P28: -0.8 | Q28: 0 | R28: -0.8 | S28: 0 | T28: 0
A29: 约束事项 | B29: 约束事项 | C29: ±5 | D29: 正负项激励 | E29: ±5
A30: 总分 | C30: 100 | E30: 100

Sheet 一部两中心
A1: 考核维度 | C1: 考核分值 | D1: 考核指标 | E1: 分值 | F1: 得分 | G1: 指标定义 | H1: 考核细则 | I1: 涉及单位 | J1: 网运中心 | K1: 网络部 | L1: 交付中心 | M1: 网运中心 | N1: 网络部 | Q1: 交付中心 | R1: 网运中心 | S1: 网络部 | V1: 交付中心 | W1: 网运中心 | X1: 网络部 | AA1: 交付中心
M2: 田泽方 | N2: 王静波 | O2: 任娟 | P2: 范帅帅 | Q2: 陈冠霖 | R2: 田泽方 | S2: 王静波 | T2: 任娟 | U2: 范帅帅 | V2: 陈冠霖 | W2: 田泽方 | X2: 王静波 | Y2: 任娟 | Z2: 范帅帅 | AA2: 陈冠霖
A3: 核心功能（45%） | B3: 网络运营 | C3: 14 | D3: 故障管控（10分） | E3: 10 | F3: 9.3 | G3: （1）故障次数管控（8分） ①指标定义 根据网络规模分地市设定S级故障发生次数管控目标，S1/S2/S3/S4级故障分别按照10次、5次、2次、1次折合故障次数。焦作目标值21。 | H3: （1）故障次数管控（8分） ①计分办法 次数低于管控目标不扣分，高于管控目标，每超出管控目标1次扣0.05分，扣完为止。 ②评价规则及数据来源 该指标按年度考核，数据来源于云网格系统。 （2）S级故障（2分） ①计分办法 a.发生S1级故障，每次扣罚0.1分;发生S2级故障，每次扣罚0.05分，扣完为止。 b.出现因人为操作不当、非割接时段动网、隐患未排查发现、隐患未及时整改引起故障的，乘系数1.2进行扣分。 ②评价规则及数据来源 该指标按年度考核，数据来源于云网格系统。 | I3: 网络部、交付中心、网运中心 | J3: 1 | K3: 1 | L3: 1 | M3: 1 | N3: 1 | O3: 1 | P3: 1 | Q3: 1 | R3: =$E3*J3*M3 -> 10 | S3: =$E3*K3*N3 -> 10 | T3: =$E3*K3*O3 -> 10 | U3: =$E3*K3*P3 -> 10 | V3: =$E3*L3*Q3 -> 10 | W3: =$F3*J3*M3 -> 9.3 | X3: =$F3*K3*N3 -> 9.3 | Y3: =$F3*K3*O3 -> 9.3 | Z3: =$F3*K3*P3 -> 9.3 | AA3: =$F3*L3*Q3 -> 9.3
D4: 能力提升（2分） | E4: 2 | F4: 2 | G4: （1）指标定义 内外部认证：，指从事线路、动力、无线、ip等专业等相关专业维护工作所涉及集团运维工程师、智网工程师、网络创新工程师以及与专业相关的外部认证。 六级人才：是指参与省公司网络线战略人才或技术人员7级工认证 | H4: （2）计分办法 内外部认证占比=内外部认证人员数量/各单位专业人员总数；内部认证目标完成率100%。 ①系统内部认证完成率，每低0.1%，扣1分； ②外部认证占比网络中心、交付考核目标30%，区县分公司考核目标15%，每低0.1%，扣1分； ③六级人才占比=六级人员数量/各单位专业人员总数要求10%以上，每低0.1%，扣1分 ④科创能力认证通过率，以科创岗位族人数为依据，考核目标60%，每低0.1%，扣1分 ⑤战略人才竞聘，各单位每新增或保持年审通过，加0.5分。 （3）评价规则及数据来源， 该指标为年度指标，数据来源省公司通报数据。 | I4: 网络部、交付中心、网运中心 | J4: 1 | K4: 1 | L4: 1 | M4: 1 | N4: 1 | O4: 1 | P4: 1 | Q4: 1 | R4: =$E4*J4*M4 -> 2 | S4: =$E4*K4*N4 -> 2 | T4: =$E4*K4*O4 -> 2 | U4: =$E4*K4*P4 -> 2 | V4: =$E4*L4*Q4 -> 2 | W4: =F4*J4*M4 -> 2 | X4: =$F4*K4*N4 -> 2 | Y4: =$F4*K4*O4 -> 2 | Z4: =$F4*K4*P4 -> 2 | AA4: =$F4*L4*Q4 -> 2
B5: 网络服务提升 | C5: 14 | D5: 移动网络满意度（5分） | E5: 5 | F5: 2.5 | G5: 1、指标定义 该指标由移动网络满意度、宽带网络满意度、智家工程师满意度三项指标构成。 | H5: 计分办法： （1）若满意度有全部明细能够区分各单位得分，按照省公司计分办法计算得分； （2）否则按照低评用户占比计算得分： ①根据各单位语音及上网具体打分情况计算低分占比情况； ②得分1分的系数为1，2-6分系数为0.5，7-8系数为0.2； ③计算1-8分得分的占比情况后计算最终得分（满分10分）； 1.当占比≤10%；得分=10−0.09×低评用户占比×100； 2.当占比介于10%和20%之间；得分=10−0.11×低评用户占比×100； 3.当占比≥20%；得分=10−0.13×低评用户占比×100； （3）最终移动网络满意度、宽带网络满意度折算为5分、智家工程师满意度折算为4分。 | I5: 网络部、网运中心 | J5: 1 | K5: 0.6 | L5: 0 | M5: 1 | N5: 0.3 | O5: 0.3 | P5: 0.6 | Q5: 0 | R5: =$E5*J5*M5 -> 5 | S5: =$E5*K5*N5 -> 0.9 | T5: =$E5*K5*O5 -> 0.9 | U5: =$E5*K5*P5 -> 1.8 | V5: =$E5*L5*Q5 -> 0 | W5: =F5*J5*M5 -> 2.5 | X5: =$F5*K5*N5 -> 0.45 | Y5: =$F5*K5*O5 -> 0.45 | Z5: =$F5*K5*P5 -> 0.9 | AA5: =$F5*L5*Q5 -> 0
D6: 宽固网络满意度（5分） | E6: 5 | F6: 3.45 | I6: 网络部、交付中心 | J6: 0 | K6: 0.6 | L6: 1 | M6: 0 | N6: 0.3 | O6: 0.6 | P6: 0.3 | Q6: 1 | R6: =$E6*J6*M6 -> 0 | S6: =$E6*K6*N6 -> 0.9 | T6: =$E6*K6*O6 -> 1.8 | U6: =$E6*K6*P6 -> 0.9 | V6: =$E6*L6*Q6 -> 5 | W6: =F6*J6*M6 -> 0 | X6: =$F6*K6*N6 -> 0.621 | Y6: =$F6*K6*O6 -> 1.242 | Z6: =$F6*K6*P6 -> 0.621 | AA6: =$F6*L6*Q6 -> 3.45
D7: 智家工程师满意度（4分） | E7: 4 | F7: 2.3927273 | I7: 网络部、交付中心 | J7: 0 | K7: 0.3 | L7: 1 | M7: 0 | N7: 0.3 | O7: 0.6 | P7: 0.3 | Q7: 1 | R7: =$E7*J7*M7 -> 0 | S7: =$E7*K7*N7 -> 0.36 | T7: =$E7*K7*O7 -> 0.72 | U7: =$E7*K7*P7 -> 0.36 | V7: =$E7*L7*Q7 -> 4 | W7: =F7*J7*M7 -> 0 | X7: =$F7*K7*N7 -> 0.21534545 | Y7: =$F7*K7*O7 -> 0.43069091 | Z7: =$F7*K7*P7 -> 0.21534545 | AA7: =$F7*L7*Q7 -> 2.3927273
B8: 网运成本管控 | C8: 17 | D8: 网络相关成本占收比（9分） | E8: 9 | F8: 9 | G8: （1）指标定义 网络相关成本占收比=（网络相关成本÷联网通信及其他业务收入）×100% 网络相关成本占收比预算目标=（网络相关成本预算÷联网通信及其他业务收入预算）×100% 网络相关成本占收比预算完成率=网络相关成本占收比÷网络相关成本占收比预算目标，焦作目标值：15.01% | H8: （2）计分办法 ①网络相关成本占收比预算完成率≤100%，得满分。 ②网络相关成本占收比预算完成率>100%，每超1PP扣本项分数的10%，线性得分。 （3）评价规则及数据来源 该指标按年度考核，数据来源于财务系统全成本报表。 | I8: 网络部、交付中心、网运中心 | J8: 0.6 | K8: 1 | L8: 0.3 | M8: 1 | N8: 1 | O8: 1 | P8: 1 | Q8: 1 | R8: =$E8*J8*M8 -> 5.4 | S8: =$E8*K8*N8 -> 9 | T8: =$E8*K8*O8 -> 9 | U8: =$E8*K8*P8 -> 9 | V8: =$E8*L8*Q8 -> 2.7 | W8: =F8*J8*M8 -> 5.4 | X8: =$F8*K8*N8 -> 9 | Y8: =$F8*K8*O8 -> 9 | Z8: =$F8*K8*P8 -> 9 | AA8: =$F8*L8*Q8 -> 2.7
D9: 铁塔差异管控（3分） | E9: 3 | F9: 3 | G9: （1）指标定义 该指标由2025年列账差异率、2025年月列账金额波动率、2023年至2025年订单退租及降配证据固化率三项指标构成。 ①2025年列账差异率=1-联通列账金额÷铁塔列账金额× 100%,增量与存量一体化管控。 ②2025年月列账金额波动幅度 =[（当月列账金额 - 上月列账金额）÷上月列账金额]×100%，考核剔除正常波动值 ③2023年至2025年订单退租及降配证据固化率=通过审核的举证材料÷2023 年 1 月 1 日至 2025 年 12 月 31 日期间造成铁塔出账差异的订单退租及降配的举证材料× 100%。 | H9: （2）计分办法 ①2026年列账差异管控≤5%，分值2分。 2026年年度列账差异管控≤5%不扣分，超过5%得0分。 ②单站租赁费≤ 1605元，分值1分。 单站租赁费≤ 1605元%不扣分，每超过 1元扣 0.1 分。 | I9: 网络部、网运中心 | J9: 0.3 | K9: 1 | L9: 0 | M9: 1 | N9: 0.3 | O9: 0.3 | P9: 1 | Q9: 0 | R9: =$E9*J9*M9 -> 0.9 | S9: =$E9*K9*N9 -> 0.9 | T9: =$E9*K9*O9 -> 0.9 | U9: =$E9*K9*P9 -> 3 | V9: =$E9*L9*Q9 -> 0 | W9: =F9*J9*M9 -> 0.9 | X9: =$F9*K9*N9 -> 0.9 | Y9: =$F9*K9*O9 -> 0.9 | Z9: =$F9*K9*P9 -> 3 | AA9: =$F9*L9*Q9 -> 0
D10: 能耗成本（5分） | E10: 5 | F10: 5 | G10: （1）指标定义 能耗成本预算完成率=（全成本科目能耗成本实际完成值/能耗成本预算目标值）×100% 能耗成本压降=各单位压降目标完成值 焦作目标值：网络线能耗成本预算目标2739万元，其他能耗成本预算目标503.6万元 能耗成本压降100万 | H10: （2）计分办法 ①能耗成本预算完成率（4分）=网络线能耗成本完成率（3分）+其他能耗成本完成率（1分） ②实际完成值≤预算目标值得满分。 ③实际完成值每超预算目标值1pp扣本项分数的10%，线性扣分，本指标分值扣完为止。 ④各单位实际完成目标压降比例线性得分，线性排名 （3）评价规则及数据来源 各单位实际完成率 | I10: 网络部、网运中心 | J10: 0.6 | K10: 1 | L10: 0 | M10: 1 | N10: 1 | O10: 0.3 | P10: 0.6 | Q10: 0 | R10: =$E10*J10*M10 -> 3 | S10: =$E10*K10*N10 -> 5 | T10: =$E10*K10*O10 -> 1.5 | U10: =$E10*K10*P10 -> 3 | V10: =$E10*L10*Q10 -> 0 | W10: =F10*J10*M10 -> 3 | X10: =$F10*K10*N10 -> 5 | Y10: =$F10*K10*O10 -> 1.5 | Z10: =$F10*K10*P10 -> 3 | AA10: =$F10*L10*Q10 -> 0
A11: 运营提升 ( 55%) | B11: 网络质量提升专项行动-工匠行动 | C11: 10 | D11: 工匠行动年度得分排名（10分） | E11: 10 | F11: 10 | G11: 1、指标定义 该指标指工匠行动年度积分排名。 | H11: （2）计分办法 工匠行动年度积分第1名的市分公司对应得满分10分。 排名2至18名的市分公司，根据其工匠行动年度积分占第一名市分公司积分的比例，同比计算本项分数。 计算公式为：本项分数 = 10 ×（分公司积分 / 第一名分公司积分） （3）评价规则及数据来源 该指标按年度考核，数据来源以省公司统一发布的工匠行动年度积分统计结果为准。 | I11: 网络部、交付中心、网运中心 | J11: 1 | K11: 1 | L11: 1 | M11: 1 | N11: 1 | O11: 1 | P11: 1 | Q11: 1 | R11: / | S11: / | T11: / | U11: / | V11: / | W11: / | X11: / | Y11: / | Z11: / | AA11: /
B12: 网络质量提升专项行动-极简网络 | C12: 10 | D12: 极简网络年度综合评价（10分） | E12: 10 | F12: 10 | G12: 1、指标定义 该指标由持续建强基础架构、常态化推进接入段光缆优化整治、提升整体运营能力三项指标构成。 （1）持续建强基础架构=2026年计划完成全量锚点机房实现网络天眼八大能力+锚点机房油机新建13台； （2）常态化推进接入段光缆优化整治=投资307万，按照各单位序时任务分解完成序时进度。 （3）提升整体运营能力=完成103个架构节点机房数字化建模+284机房数字化验收。 | H12: 2、计分办法 （1）持续建强基础架构年底前完成100%，得2.9分，每低于1pp扣基本分*1%，扣完本项分值为止。 （2）常态化推进接入段光缆优化整治月度目标完成100%，得4分，每低于1pp扣基本分*1%，扣完本项分值为止。 （3）提升整体运营能力月度目标完成100%，得3分，每低于1pp扣基本分*1%，扣完本项分值为止 （4）集团公司每采纳极简网络一个案例，对应市公司加0.1分。 （5）极简网络总体得分不超过10分。 | I12: 网络部、交付中心、网运中心 | J12: 1 | K12: 1 | L12: 1 | M12: 1 | N12: 1 | O12: 1 | P12: 1 | Q12: 1 | R12: =$E12*J12*M12 -> 10 | S12: =$E12*K12*N12 -> 10 | T12: =$E12*K12*O12 -> 10 | U12: =$E12*K12*P12 -> 10 | V12: =$E12*L12*Q12 -> 10 | W12: =F12*J12*M12 -> 10 | X12: =$F12*K12*N12 -> 10 | Y12: =$F12*K12*O12 -> 10 | Z12: =$F12*K12*P12 -> 10 | AA12: =$F12*L12*Q12 -> 10
B13: 网络质量提升专项行动-网络运营安全深化年 | C13: 6 | D13: 同路由整治处理（2分） | E13: 2 | F13: 2 | G13: 1、指标定义 （1）所有达到S级机房完成纯物理双路由整改（包括同井，同馈窗）； （2）所有上联业务完成不同环路整改。 | H13: 2、计分办法 （1）全量双路由整改年底前完成100%，得50%得分，每低于1pp扣0.2，扣完本项分值为止。 （2）上联业务不同环路整改二季度完成100%，得50%得分，每低于1pp扣0.2，扣完本项分值为止。 | I13: 网络部、交付中心、网运中心 | J13: 1 | K13: 1 | L13: 1 | M13: 1 | N13: 1 | O13: 0.3 | P13: 0.3 | Q13: 1 | R13: =$E13*J13*M13 -> 2 | S13: =$E13*K13*N13 -> 2 | T13: =$E13*K13*O13 -> 0.6 | U13: =$E13*K13*P13 -> 0.6 | V13: =$E13*L13*Q13 -> 2 | W13: =F13*J13*M13 -> 2 | X13: =$F13*K13*N13 -> 2 | Y13: =$F13*K13*O13 -> 0.6 | Z13: =$F13*K13*P13 -> 0.6 | AA13: =$F13*L13*Q13 -> 2
D14: 网络安全事件（4分） | E14: 4 | F14: 4 | G14: （1）指标定义 该指标由账号管理安全事件、违规动网操作、违规数据配置、违规分光事件四项指标构成。 | H14: （2）计分办法 ①发生账号管理安全事件扣1分，最多扣1分。 ②发现一起违规动网操作扣0.2分，因违规动网操作导致发生较大及以上网络故障或网络安全责任事件扣1分，最多扣1分。 ③发现一起违规数据配置扣0.2分，因违规数据配置导致发生较大及以上网络故障或网络安全责任事件扣1分，最多扣1分。 ④发生违规分光事件扣1分，因违规分光导致发生较大及以上网络故障或网络安全责任事件扣4分，最多扣4分。 ⑤被上级单位通报的加倍扣分，最多扣4分。 （3）评价规则及数据来源 该指标按年度进行考核，数据来源于上级单位/省公司通报。 | I14: 网络部、交付中心、网运中心 | J14: 1 | K14: 1 | L14: 1 | M14: 1 | N14: 1 | O14: 1 | P14: 1 | Q14: 1 | R14: =$E14*J14*M14 -> 4 | S14: =$E14*K14*N14 -> 4 | T14: =$E14*K14*O14 -> 4 | U14: =$E14*K14*P14 -> 4 | V14: =$E14*L14*Q14 -> 4 | W14: =F14*J14*M14 -> 4 | X14: =$F14*K14*N14 -> 4 | Y14: =$F14*K14*O14 -> 4 | Z14: =$F14*K14*P14 -> 4 | AA14: =$F14*L14*Q14 -> 4
B15: 网络服务提升专项行动-移网质量提升 | C15: 11 | D15: 重点场景提升（3分） | E15: 3 | F15: 2.57 | G15: （1）指标定义 该指标由非住宅达标率、住宅专项（A类+千户覆盖达标率）、住宅专项（新建住宅覆盖达标率）、地下空间完成情况（上报及时率及地下空间建设目标完成率）四项指标组成。 | H15: （2）计分办法 ①非住宅场景达标100%（1分） 非住宅达标率100%满分，<85%得0分，中间线性记分。 ②A类+千户场景达标率100%（1分） A类+千户移网覆盖达标率100%满分，<85%得0分，中间线性记分。 ③新建住宅场景达标率100%（0.5分） 新建住宅移网覆盖达标率100%满分，<85%得0分，中间线性记分。 ④工信部覆盖达标率100%（0.5分） 工信部覆盖达标率100%满分，<85%得0分，中间线性记分。 区县建设任务得分取自本地市建设任务得分，每月低于当月建设目标值1%，则线性扣分0.1分，扣完为止。 （3）评价规则及数据来源 该指标按年度进行考核，数据来源于集团评估通报及省内自评。 | I15: 网络部、网运中心 | J15: 1 | K15: 0.3 | L15: 0 | M15: 1 | N15: 0.3 | O15: 0.3 | P15: 1 | Q15: 0 | R15: =$E15*J15*M15 -> 3 | S15: =$E15*K15*N15 -> 0.27 | T15: =$E15*K15*O15 -> 0.27 | U15: =$E15*K15*P15 -> 0.9 | V15: =$E15*L15*Q15 -> 0 | W15: =F15*J15*M15 -> 2.57 | X15: =$F15*K15*N15 -> 0.2313 | Y15: =$F15*K15*O15 -> 0.2313 | Z15: =$F15*K15*P15 -> 0.771 | AA15: =$F15*L15*Q15 -> 0
D16: 移网问题栅格改善（3分） | E16: 3 | F16: 3 | G16: （1）指标定义 该指标指年度移网问题栅格改善率。 年度移网问题栅格改善率=12期拍照问题栅格改善数/本年12期拍照问题栅格数。 ①移网问题栅格判定标准：逐月对月移网投诉量≥3或移网服请不满≥4的问题栅格拍照，认定移网问题栅格。 ②问题栅格改善标准：移网问题栅格设定1个月的改善期，省分闭环解决网络问题，并保持改善效果；改善期后，如连续2个月投诉量＜3或移网服请不满＜4，视为问题栅格改善。 | H16: （2）计分办法 ①问题栅格改善率达标目标值80%。 ②达标得满分3分，不达标0分。 （3）评价规则及数据来源 该指标按月跟踪通报，以全年累计改善率计算年度得分。数据来源于集团公司客户服务运营平台。 | I16: 网络部、网运中心 | J16: 1 | K16: 1 | L16: 0 | M16: 1 | N16: 0.3 | O16: 0.3 | P16: 1 | Q16: 0 | R16: =$E16*J16*M16 -> 3 | S16: =$E16*K16*N16 -> 0.9 | T16: =$E16*K16*O16 -> 0.9 | U16: =$E16*K16*P16 -> 3 | V16: =$E16*L16*Q16 -> 0 | W16: =F16*J16*M16 -> 3 | X16: =$F16*K16*N16 -> 0.9 | Y16: =$F16*K16*O16 -> 0.9 | Z16: =$F16*K16*P16 -> 3 | AA16: =$F16*L16*Q16 -> 0
D17: 业务感知提升（4分） | E17: 4 | F17: 2.54 | G17: （1）指标定义 该指标由语音业务良好体验率、语音业务感知掉话率、4G数据业务卡顿小区比例、5G数据业务卡顿小区比例、同站重复故障比例五项指标构成。 ①语音业务良好体验率=语音业务良好体验次数/语音业务次数 a.语音业务良好体验次数 = 同时满足“接得通”、“接得快”、“听得清”、“不掉话”的业务次数 ，被叫为移动、电信、固网时，语音业务良好体验只需满足“接得通”、“听得清”、“不掉话”； ②语音业务感知掉话率=语音业务感知掉话次数/语音业务次数 针对双方都是联通移网用户的语音通话进行评价。如果二者之间上一次通话时长超过2秒钟，并且上一次通话结束后40秒之内又发起呼叫（上一次通话的主被叫发起呼叫皆可），排除第二次呼叫拒接、运营商测试以及短号码等因素之后，将上一次通话定义为语音业务感知掉话； ③4G数据业务卡顿小区比例=4G数据业务卡顿小区/4G小区总数 ④5G数据业务卡顿小区比例=5G数据业务卡顿小区/5G小区总数 下行时延大于 200ms 概率超过 10%，记为卡顿小区。(电信 800M小区不纳入考核；联通 900M 小区时延大于 200ms 概率超过 20%，记为卡顿小区。) ⑤同站重复故障比例=（当月同站重复故障数量+集码BBU原因造成的重复故障+连续两个月同站重复故障）/当月物理站址故障总量*100%。 | H17: （2）计分办法 ①语音业务良好体验率≥97%（2分） 达标得满分，＜96%得0分，[96%,97%)线性打分。 ②数据业务体验良好率≥97%（2分） 达标得满分，＜96%得0分，[96%,97%)线性打分。 | I17: 网络部、网运中心 | J17: 1 | K17: 0.3 | L17: 0 | M17: 1 | N17: 0.3 | O17: 0.3 | P17: 1 | Q17: 0 | R17: =$E17*J17*M17 -> 4 | S17: =$E17*K17*N17 -> 0.36 | T17: =$E17*K17*O17 -> 0.36 | U17: =$E17*K17*P17 -> 1.2 | V17: =$E17*L17*Q17 -> 0 | W17: =F17*J17*M17 -> 2.54 | X17: =$F17*K17*N17 -> 0.2286 | Y17: =$F17*K17*O17 -> 0.2286 | Z17: =$F17*K17*P17 -> 0.762 | AA17: =$F17*L17*Q17 -> 0
D18: 移网资源利用率（1分） | E18: 1 | F18: 1 | G18: （1）指标定义 该指标指综合考虑3.5GHz、2.1GHz、900M无线资源利用率情况，并基于各频段下行频率资源和小区数进行加权统计。 ①移动资源利用率=[7*3.5GHz宏站小区规模*3.5GHz宏站小区无线资源利用率+2*2.1GHz（20M带宽）宏站小区规模*2.1GHz（20M带宽）宏站小区无线资源利用率+4*2.1GHz（40M带宽）宏站小区规模*2.1GHz（40M带宽）宏站小区无线资源利用率+900MHz宏站小区规模*900MHz宏站小区资源利用率]/(7*3.5GHz宏站小区规模+2*2.1GHz（20M带宽）宏站小区规模+4*2.1GHz（40M带宽）宏站小区规模+900MHz宏站小区规模)。 ②5G中频宏站小区无线资源利用率=Σ(小区自忙时下行PDSCH信道占用PRB个数*相应PRB调用层数）/Σ(小区自忙时的每空分流下行PDSCH信道可用PRB个数*小区下行时域平均最大调度层数(剔除0值))/K值，其中5G中频包括3.5GHz、2.1GHz（20M带宽）、2.1GHz（40M带宽），Σ表示所有5G中频宏站按小区求和，K值取典型值50%。 ③900MHz宏站小区资源利用率=（L900下行PRB占用数/L900下行PRB可用数）*L900小区数量占比+（NR900下行PRB占用数/NR900下行PRB可用数）*NR900小区数量占比。 | H18: （2）计分办法 目标无线资源利用率≥30%。 ①完成值大于等于达标值得满分； ②完成值低于基准值（2026年1月指标）不得分； ③完成值相较于2026年1月基准值未提升，得满分的80%； ④完成值低于达标值，但实现提升的，按照完成情况在满分与满分的80%之间线性计分。 （3）评价规则及数据来源 该指标按年度进行考核，数据来源于集团通报。 | I18: 网络部、网运中心 | J18: 1 | K18: 1 | L18: 0 | M18: 1 | N18: 0.3 | O18: 0.3 | P18: 1 | Q18: 0 | R18: =$E18*J18*M18 -> 1 | S18: =$E18*K18*N18 -> 0.3 | T18: =$E18*K18*O18 -> 0.3 | U18: =$E18*K18*P18 -> 1 | V18: =$E18*L18*Q18 -> 0 | W18: =F18*J18*M18 -> 1 | X18: =$F18*K18*N18 -> 0.3 | Y18: =$F18*K18*O18 -> 0.3 | Z18: =$F18*K18*P18 -> 1 | AA18: =$F18*L18*Q18 -> 0
B19: 网络服务提升专项行动-智家网络服务提升 | C19: 13 | D19: 交付质量提升（4分） | E19: 4 | F19: 3.1371429 | G19: （1）指标定义 该指标由装维动作合格率、456标准修障达标率两项指标构成。 ①装维动作合格率=1-不满足装维要求的装维动作总量/装维总量 ②456标准修障达标率=（16点前生单且在456时限内修复的工单数+16点后生单且在第二天12:00前修复的工单数）/（本周期内的竣工单+所选周期结束时间的在途工单） | H19: （2）计分办法 ①各项设定达标值和基准值，高于达标值得满分、低于基准值不得分，在达标值和基准值之间的线性计分。 ②装维动作合格率（2分），达标值≥98.5%，基准值≥95%。 ③456标准修障达标率（2分），达标值≥80%，基准值≥70%。 a.若修机当日好≥90%，456标准修障达标率评价值取实际完成值； b.若修机当日好＜90%，456标准修障达标率评价值=456标准修障达标率实际完成值*修机当日好率。 （3）评价规则及数据来源 该指标按月评价计分，以月指标得分的均值计算年度得分。数据来源于宽带网络数字化运营平台、经营分析系统。 | I19: 网络部、交付中心 | J19: 0 | K19: 0.3 | L19: 1 | M19: 0 | N19: 0.3 | O19: 1 | P19: 0.3 | Q19: 1 | R19: =$E19*J19*M19 -> 0 | S19: =$E19*K19*N19 -> 0.36 | T19: =$E19*K19*O19 -> 1.2 | U19: =$E19*K19*P19 -> 0.36 | V19: =$E19*L19*Q19 -> 4 | W19: =F19*J19*M19 -> 0 | X19: =$F19*K19*N19 -> 0.28234286 | Y19: =$F19*K19*O19 -> 0.94114286 | Z19: =$F19*K19*P19 -> 0.28234286 | AA19: =$F19*L19*Q19 -> 3.1371429
D20: 宽带资源效能提升（3分） | E20: 3 | F20: 3 | G20: （1）指标定义 该指标由全量宽带端口利用率、存量资源准确率、新装宽带一次核配准确率三项指标构成。 ①全量宽带端口利用率=所有接入方式下宽带占用端口数/（FTTH端口总量+PON_LAN数据端口总量）。 ②新增号线资源规范率=四项标准都通过的新增末梢分光器/全量的新增末梢分光器 ③新装宽带一次核配准确率=一次性完成资源核配并成功施工报竣的装移机工单数量/新装宽带工单总量*100％。 | H20: （2）计分办法 各项设定基准值和达标值，高于达标值得满分、低于基准值不得分，在达标值和基准值之间的线性计分。 ①全量宽带端口利用率（1分），分地市确定设置基准值、达标值。各地市目标如下：57.92%。 完成值≥达标值得1分；完成值低于基准值得0.8分；完成值低于达标值，但高于基准值的，按照提升值在1分与0.8分之间线性计分。 ②新增号线资源规范率（1分）、新装宽带一次核配准确率（1分），基准值为≥82%，达标值为≥92%。 a.完成值≥92%得1分，完成值＜82%不得分，82%-92%之间线性打分。 b.新装宽带一次核配准确率具备打分条件之前，按照存量资源准确率打分；具备打分条件之后，按照两个子指标分别打分。 （3）评价规则及数据来源 ①全量宽带端口利用率取12月数据进行评价； ②新增号线资源规范率Q1≥70%；Q2≥90%；Q3≥95%；Q4≥95%,未完成序时进度扣1分 ③数据来源于号线资源分析系统、宽带网络数字化运营平台。 | I20: 网络部、交付中心、网运中心 | J20: 0 | K20: 1 | L20: 1 | M20: 0 | N20: 0.3 | O20: 1 | P20: 0.3 | Q20: 1 | R20: =$E20*J20*M20 -> 0 | S20: =$E20*K20*N20 -> 0.9 | T20: =$E20*K20*O20 -> 3 | U20: =$E20*K20*P20 -> 0.9 | V20: =$E20*L20*Q20 -> 3 | W20: =F20*J20*M20 -> 0 | X20: =$F20*K20*N20 -> 0.9 | Y20: =$F20*K20*O20 -> 3 | Z20: =$F20*K20*P20 -> 0.9 | AA20: =$F20*L20*Q20 -> 3
D21: 客户感知提升（6分） | E21: 3 | F21: 3 | G21: （1）指标定义 该指标由PON口在服率、PON口质差率、全量宽带故障率（10010+96480）、宽带投诉率、网络服务感知综合评价四项指标构成。 其中网络服务综合感知评价=响应率*10%+解决率*40%+满意率*50%，包括投诉、故障和咨办工单。 | H21: （2）计分办法 ①各项设定达标值和基准值，高于达标值得满分、低于基准值不得分，在达标值和基准值之间的线性计分。 ②PON口在服率（1分），达标值≥99.5%，基准值≥99%。若当月出现规模故障，按次评价，每发生一次当月扣0.5分。 ③PON口质差率（2分），达标值≤2.0%，基准值≤2.24%。若当月出现规模故障，按次评价，每发生一次当月扣0.5分。 （3）评价规则及数据来源 该指标按月评价计分，以月度得分均值计算年度得分。数据来源于宽带网络数字化运营平台、中国联通客服运营平台、经营分析系统。 | I21: 网络部、网运中心 | J21: 1 | K21: 0.6 | L21: 0.3 | M21: 1 | N21: 1 | O21: 1 | P21: 0.3 | Q21: 1 | R21: =$E21*J21*M21 -> 3 | S21: =$E21*K21*N21 -> 1.8 | T21: =$E21*K21*O21 -> 1.8 | U21: =$E21*K21*P21 -> 0.54 | V21: =$E21*L21*Q21 -> 0.9 | W21: =F21*J21*M21 -> 3 | X21: =$F21*K21*N21 -> 1.8 | Y21: =$F21*K21*O21 -> 1.8 | Z21: =$F21*K21*P21 -> 0.54 | AA21: =$F21*L21*Q21 -> 0.9
E22: 3 | F22: 3 | H22: （2）计分办法 ①各项设定达标值和基准值，高于达标值得满分、低于基准值不得分，在达标值和基准值之间的线性计分。 ③全量宽带故障率（1分），达标值≤90件/万户，基准值≤110件/万户。 ④宽带投诉率（1分），达标值≤1.3件/万户，基准值≤4件/万户。 ⑤网络服务综合感知评价（1分），达标值≥95%，基准值≥92%。 a.若96480服务满意率≥95%，网络服务综合感知评价取实际完成值； b.若96480服务满意率＜95%，网络服务综合感知评价=网络服务综合感知评价实际完成值*96480服务满意率。 （3）评价规则及数据来源 该指标按月评价计分，以月度得分均值计算年度得分。数据来源于宽带网络数字化运营平台、中国联通客服运营平台、经营分析系统。 | I22: 网络部、交付中心 | J22: 0 | K22: 0.3 | L22: 1 | M22: 0 | N22: 0.3 | O22: 1 | P22: 0.3 | Q22: 1 | R22: =$E22*J22*M22 -> 0 | S22: =$E22*K22*N22 -> 0.27 | T22: =$E22*K22*O22 -> 0.9 | U22: =$E22*K22*P22 -> 0.27 | V22: =$E22*L22*Q22 -> 3 | W22: =F22*J22*M22 -> 0 | X22: =$F22*K22*N22 -> 0.27 | Y22: =$F22*K22*O22 -> 0.9 | Z22: =$F22*K22*P22 -> 0.27 | AA22: =$F22*L22*Q22 -> 3
B23: 网络服务提升专项行动-政企双线网络服务提升 | C23: 5 | D23: 政企双线交付及时率（1分） | E23: 1 | F23: 1 | G23: （1）指标定义 该指标由全量宽带端口利用率、社会地址住宅小区全里末梢分光器准确率、新装宽带一次核配准确率三项、指标构成。 ①全量宽带端口利用率=所有接入方式下宽带占用端口数/（FTTH端口总量+PON_LAN数据端口总量）。 ②新装宽带一次核配准确率=一次性完成资源核配并成功施工报竣的装移机工单数量/新装宽带工单总量*100％。 | H23: （2）计分办法 各项设定基准值和达标值，高于达标值得满分、低于基准值不得分，在达标值和基准值之间的线性计分。 ①全量宽带端口利用率（1分），分地市确定设置基准值、达标值。各地市目标如下：57.92%。 完成值≥达标值得1分；完成值低于基准值得0.8分；完成值低于达标值，但高于基准值的，按照提升值在1分与0.8分之间线性计分。 ②社会地址住宅小区全里末梢分光器准确率：4月之后保持成功率≥92%，每低目标值1个百分点，减0.5分 b.新装宽带一次核配准确率具备打分条件之前，按照存量资源准确率打分；具备打分条件之后，按照两个子指标分别打分。 （3）评价规则及数据来源 ①全量宽带端口利用率取12月数据进行评价； ②新增号线资源规范率Q1≥70%；Q2≥90%；Q3≥95%；Q4≥95%,未完成序时进度扣1分 ③数据来源于号线资源分析系统、宽带网络数字化运营平台。 | I23: 网络部、交付中心 | J23: 0 | K23: 0.6 | L23: 1 | M23: 0 | N23: 0.3 | O23: 1 | P23: 0.3 | Q23: 1 | R23: =$E23*J23*M23 -> 0 | S23: =$E23*K23*N23 -> 0.18 | T23: =$E23*K23*O23 -> 0.6 | U23: =$E23*K23*P23 -> 0.18 | V23: =$E23*L23*Q23 -> 1 | W23: =F23*J23*M23 -> 0 | X23: =$F23*K23*N23 -> 0.18 | Y23: =$F23*K23*O23 -> 0.6 | Z23: =$F23*K23*P23 -> 0.18 | AA23: =$F23*L23*Q23 -> 1
D24: 政企双线故障管控（2分） | E24: 2 | F24: 2 | G24: （1）指标定义 该指标由政企双线故障4小时处理及时率、政企双线监控告警返单及时率两项指标构成。 | H24: （2）计分办法 ①政企双线故障4小时处理及时率=1-（不及时处理政企双线故障次数÷应处理政企双线故障总次数）×100%，满分1分，基本分0.8分，低于98%不得分，98%-100%之间线性得分，线性部分得分=0.2*（完成值-98%）/(100%-98%)； ②政企双线监控告警返单及时率=1-处理超时的政企双线告警工单数/政企双线告警工单总数，满分1分； （3）评价规则及数据来源 该指标按月评价计分，以月度得分均值计算年度得分。数据来源于OSS2.0业务故障2.0、智慧派单系统。 | I24: 网络部、交付中心 | J24: 0 | K24: 0.6 | L24: 1 | M24: 0 | N24: 0.3 | O24: 1 | P24: 0.3 | Q24: 1 | R24: =$E24*J24*M24 -> 0 | S24: =$E24*K24*N24 -> 0.36 | T24: =$E24*K24*O24 -> 1.2 | U24: =$E24*K24*P24 -> 0.36 | V24: =$E24*L24*Q24 -> 2 | W24: =F24*J24*M24 -> 0 | X24: =$F24*K24*N24 -> 0.36 | Y24: =$F24*K24*O24 -> 1.2 | Z24: =$F24*K24*P24 -> 0.36 | AA24: =$F24*L24*Q24 -> 2
D25: 政企双线资源治理（2分） | E25: 2 | F25: 2 | G25: （1）指标定义 该指标由政企双线电路拼接、政企双线末端光设施绑定标准地址完整率、B-O-O数据一致性稽核、资源一次自动核配成功率、互联网专线自动开通成功率构成。 互联网专线自动开通成功率=全程自动核配成功率*数据自动制作成功率 | H25: （2）计分办法 ①政企电路拼接完成率：4月之后保持成功率≥98.5%，每低目标值1个百分点，减0.5分 ②政企双线末端光设施绑定标准地址完整率=绑定的政企电路数/全量政企电路数，4月之后保持成功率≥98.5%，每低目标值1个百分点，减0.5分 ③ 双线BOO数据一致率=BO数据一致率*0.4+OO数据一致率*0.6 1、BO数据一致率=BO数量一致率*0.3+BO状态一致率*0.3+BO速率一致率*0.3+BO类型一致率*0.1 注：“BO数量、状态、速率、类型一致率”指B域系统与O域网络资源系统数据稽核一致率。 2、OO数据一致率=OO数量一致率*0.4+OO状态一致率*0.3+OO速率一致率*0.3。目标值96%，完成目标得满分，每低目标值1个百分点，减0.3分. ④资源一次自动核配成功率：4月≥10%；5月≥20%；6月≥30%；7月≥40%；8月≥50%；9月≥60%；10月≥70%；11月以后≥80%，每低目标值1个百分点，减0.3分 ⑤互联网专线自动开通成功率 4月-6月基准值20%、达标值30%，≥30%得满分，<20%不得分，中间线性得分 7月-9月基准值30%、达标值60%，≥60%得满分，<30%不得分，中间线性得分 10月-12月基准值60%、达标值90%，≥90%得满分，<60%不得分，中间线性得分 （3）评价规则及数据来源 该指标按月评价计分，以月度得分均值计算年度得分。数据来源于网络资源中心、B域客户订单、O域网络资源中心和O域网管系统、云网格系统。 | I25: 网络部、交付中心 | J25: 0 | K25: 0.3 | L25: 1 | M25: 0 | N25: 0.3 | O25: 1 | P25: 0.3 | Q25: 1 | R25: =$E25*J25*M25 -> 0 | S25: =$E25*K25*N25 -> 0.18 | T25: =$E25*K25*O25 -> 0.6 | U25: =$E25*K25*P25 -> 0.18 | V25: =$E25*L25*Q25 -> 2 | W25: =F25*J25*M25 -> 0 | X25: =$F25*K25*N25 -> 0.18 | Y25: =$F25*K25*O25 -> 0.6 | Z25: =$F25*K25*P25 -> 0.18 | AA25: =$F25*L25*Q25 -> 2
A26: 端网业协同 | B26: 端网业协同 | C26: 10 | D26: 5G登网率 | E26: 3 | F26: / | G26: （1）指标定义 5G签约用户5G终端登网 | H26: （2）计分办法 月度清单制推进5G终端SA开关打开，按月度目标完成率在60%到100%间线性得分，低于60%不得分 | I26: 网络部、网运中心 | J26: 1 | K26: 1 | L26: 0 | M26: 1 | N26: 0.3 | O26: 0.3 | P26: 1 | Q26: 0 | R26: / | S26: / | T26: / | U26: / | V26: / | W26: / | X26: / | Y26: / | Z26: / | AA26: /
D27: 千兆化 | E27: 7 | F27: 7 | G27: （1）指标定义 该指标由路由器压降目标完成率、低速通道整治完成率、终端匹配套餐升级整治完成率组成构成。 | H27: （2）计分办法 按时序进度完成率进行考核，达标不扣分，不达标线性扣分。 | I27: 网络部、交付中心 | J27: 0 | K27: 0.3 | L27: 1 | M27: 0 | N27: 0.3 | O27: 1 | P27: 0.3 | Q27: 1 | R27: =$E27*J27*M27 -> 0 | S27: =$E27*K27*N27 -> 0.63 | T27: =$E27*K27*O27 -> 2.1 | U27: =$E27*K27*P27 -> 0.63 | V27: =$E27*L27*Q27 -> 7 | W27: =F27*J27*M27 -> 0 | X27: =$F27*K27*N27 -> 0.63 | Y27: =$F27*K27*O27 -> 2.1 | Z27: =$F27*K27*P27 -> 0.63 | AA27: =$F27*L27*Q27 -> 7
A28: 公司KPI保障 | B28: 公司KPI保障 | C28: -3 | D28: 科技创新（2分） | E28: 2 | F28: 2 | G28: （1）指标定义 科技创新研发投入贡献 | H28: ①科技创新研发项目无项目扣1分 ②每月工时未及时录入扣1分 | I28: 网络部、交付中心、网运中心 | J28: 1 | K28: 1 | L28: 1 | M28: 1 | N28: 0.6 | O28: 0.6 | P28: 1 | Q28: 1 | R28: =$E28*J28*M28 -> 2 | S28: =$E28*K28*N28 -> 1.2 | T28: =$E28*K28*O28 -> 1.2 | U28: =$E28*K28*P28 -> 2 | V28: =$E28*L28*Q28 -> 2 | W28: =F28*J28*M28 -> 2 | X28: =$F28*K28*N28 -> 1.2 | Y28: =$F28*K28*O28 -> 1.2 | Z28: =$F28*K28*P28 -> 2 | AA28: =$F28*L28*Q28 -> 2
D29: 反诈治理 | E29: -5 | F29: -1.2 | G29: (1)指标定义 该指标由涉案号码治理、政企业务涉案治理、信安工单综合评价率、“内鬼”事件四项指标组成。 | H29: （2）计分方法 指标A:涉案号码治理(1.5分)：1、A1涉案电话号码（含手机号码和固话号码）数量同比下降，得0.5分，同比上升60%得0分，在此之间线性得分。2、当地行业移动电话号码涉案占比偏差率（简称“A2”）：A2≤0.9得1分，A2>1.5不得分，在此之间线性计分。 指标B:政企业务涉案治理（2分）：行业短信端口年度涉案量≤15，得1分；政企固话业务年度涉案量≤2，得1分，或涉案量系统内占比低于用户数占比得1分，高于10个百分点得0分，在此之间线性得分。 指标C：信安工单综合评价率（1分）：2026年信安工单综合评价率全年月均达到92.6%及以上的，得1分；90%-92.6%线性得分，低于90%不得分； 指标D：“内鬼”事件（0.5分） 市场发展、业务合作、IT支撑、渠道管理、网络运营及建设等领域，2026年没有新发生的“内鬼”事件，得满分；发生内鬼事件，视情况扣0.2-0.5分。 | I29: 网络部、交付中心、网运中心 | J29: 1 | K29: 1 | L29: 1 | M29: 1 | N29: 1 | O29: 1 | P29: 1 | Q29: 1 | R29: 0 | S29: 0 | T29: 0 | U29: 0 | V29: 0 | W29: =F29*J29*M29 -> -1.2 | X29: =$F29*K29*N29 -> -1.2 | Y29: =$F29*K29*O29 -> -1.2 | Z29: =$F29*K29*P29 -> -1.2 | AA29: =$F29*L29*Q29 -> -1.2
A30: 约束事项 | B30: 约束事项 | C30: ±5 | D30: 正负项激励 | E30: ±5 | F30: 0 | R30: =SUM(R3:R29) -> 58.3 | S30: =SUM(S3:S29) -> 52.77 | T30: =SUM(T3:T29) -> 55.85 | U30: =SUM(U3:U29) -> 56.18 | V30: =SUM(V3:V29) -> 64.6 | W30: =SUM(W3:W29) -> 52.01 | X30: =SUM(X3:X29) -> 49.748588 | Y30: =SUM(Y3:Y29) -> 52.223734 | ... AA30: =SUM(AA3:AA29) -> 58.67987
A31: 总分 | C31: 100 | E31: 100 | W31: =W30/R30*100 -> 89.210978 | X31: =X30/S30*100 -> 94.274376 | Y31: =Y30/T30*100 -> 93.507133 | Z31: =Z30/U30*100 -> 93.114433 | AA31: =AA30/V30*100 -> 90.835712
X32: =AVERAGE(X31:Z31) -> 93.631981

Sheet 县
A1: 考核维度 | C1: 考核分值 | D1: 考核指标 | E1: 本地分值 | F1: 县公司拟定分值 | G1: 指标定义 | H1: 考核细则 | I1: 修武 | J1: 博爱 | K1: 武陟 | L1: 沁阳 | M1: 孟州 | N1: 温县 | O1: 修武 | P1: 博爱 | Q1: 武陟 | R1: 沁阳 | S1: 孟州 | T1: 温县
A2: 核心功能（45%） | B2: 网络运营 | C2: 12 | D2: 故障管控（10分） | E2: 10 | F2: 10 | G2: （1）故障次数管控（8分） ①指标定义 根据网络规模分地市设定S级故障发生次数管控目标，S1/S2/S3/S4级故障分别按照10次、5次、2次、1次折合故障次数。焦作目标值21。 | H2: （1）故障次数管控（8分） ①计分办法 次数低于管控目标不扣分，高于管控目标，每超出管控目标1次扣0.05分，扣完为止。 ②评价规则及数据来源 该指标按年度考核，数据来源于云网格系统。 （2）S级故障（2分） ①计分办法 a.发生S1级故障，每次扣罚0.1分;发生S2级故障，每次扣罚0.05分，扣完为止。 b.出现因人为操作不当、非割接时段动网、隐患未排查发现、隐患未及时整改引起故障的，乘系数1.2进行扣分。 ②评价规则及数据来源 该指标按年度考核，数据来源于云网格系统。 | I2: =VLOOKUP(D2,'6月'!D:K,8,0) -> 9.1 | J2: =VLOOKUP(D2,'6月'!D:L,9,0) -> 9.1 | K2: =VLOOKUP(D2,'6月'!D:M,10,0) -> 9 | L2: =VLOOKUP(D2,'6月'!D:N,11,0) -> 8.7 | M2: =VLOOKUP(D2,'6月'!D:O,12,0) -> 9.3 | N2: =VLOOKUP(D2,'6月'!D:P,13,0) -> 9.1 | O2: =I2/$E2*$F2 -> 9.1 | P2: =J2/$E2*$F2 -> 9.1 | Q2: =K2/$E2*$F2 -> 9 | R2: =L2/$E2*$F2 -> 8.7 | S2: =M2/$E2*$F2 -> 9.3 | T2: =N2/$E2*$F2 -> 9.1
D3: 能力提升（2分） | E3: 2 | F3: 2 | G3: （1）指标定义 内外部认证：，指从事线路、动力、无线、ip等专业等相关专业维护工作所涉及集团运维工程师、智网工程师、网络创新工程师以及与专业相关的外部认证。 六级人才：是指参与省公司网络线战略人才或技术人员7级工认证 | H3: （2）计分办法 内外部认证占比=内外部认证人员数量/各单位专业人员总数；内部认证目标完成率100%。 ①系统内部认证完成率，每低0.1%，扣1分； ②外部认证占比网络中心、交付考核目标30%，区县分公司考核目标15%，每低0.1%，扣1分； ③六级人才占比=六级人员数量/各单位专业人员总数要求10%以上，每低0.1%，扣1分 ④科创能力认证通过率，以科创岗位族人数为依据，考核目标60%，每低0.1%，扣1分 ⑤战略人才竞聘，各单位每新增或保持年审通过，加0.5分。 （3）评价规则及数据来源， 该指标为年度指标，数据来源省公司通报数据。 | I3: =VLOOKUP(D3,'6月'!D:K,8,0) -> 2 | J3: =VLOOKUP(D3,'6月'!D:L,9,0) -> 2 | K3: =VLOOKUP(D3,'6月'!D:M,10,0) -> 2 | L3: =VLOOKUP(D3,'6月'!D:N,11,0) -> 2 | M3: =VLOOKUP(D3,'6月'!D:O,12,0) -> 2 | N3: =VLOOKUP(D3,'6月'!D:P,13,0) -> 2 | O3: =I3/$E3*$F3 -> 2 | P3: =J3/$E3*$F3 -> 2 | Q3: =K3/$E3*$F3 -> 2 | R3: =L3/$E3*$F3 -> 2 | S3: =M3/$E3*$F3 -> 2 | T3: =N3/$E3*$F3 -> 2
B4: 网络服务提升 | C4: 13 | D4: 移动网络满意度（5分） | E4: 5 | F4: 5 | G4: 1、指标定义 该指标由移动网络满意度、宽带网络满意度、智家工程师满意度三项指标构成。 | H4: 计分办法： （1）若满意度有全部明细能够区分各单位得分，按照省公司计分办法计算得分； （2）否则按照低评用户占比计算得分： ①根据各单位语音及上网具体打分情况计算低分占比情况； ②得分1分的系数为1，2-6分系数为0.5，7-8系数为0.2； ③计算1-8分得分的占比情况后计算最终得分（满分10分）； 1.当占比≤10%；得分=10−0.09×低评用户占比×100； 2.当占比介于10%和20%之间；得分=10−0.11×低评用户占比×100； 3.当占比≥20%；得分=10−0.13×低评用户占比×100； （3）最终移动网络满意度、宽带网络满意度折算为5分、智家工程师满意度折算为4分。 | I4: =VLOOKUP(D4,'6月'!D:K,8,0) -> 2.5 | J4: =VLOOKUP(D4,'6月'!D:L,9,0) -> 2.5 | K4: =VLOOKUP(D4,'6月'!D:M,10,0) -> 2.5 | L4: =VLOOKUP(D4,'6月'!D:N,11,0) -> 2.5 | M4: =VLOOKUP(D4,'6月'!D:O,12,0) -> 2.5 | N4: =VLOOKUP(D4,'6月'!D:P,13,0) -> 2.5 | O4: =I4/$E4*$F4 -> 2.5 | P4: =J4/$E4*$F4 -> 2.5 | Q4: =K4/$E4*$F4 -> 2.5 | R4: =L4/$E4*$F4 -> 2.5 | S4: =M4/$E4*$F4 -> 2.5 | T4: =N4/$E4*$F4 -> 2.5
D5: 宽固网络满意度（5分） | E5: 5 | F5: 5 | I5: =VLOOKUP(D5,'6月'!D:K,8,0) -> 3.9 | J5: =VLOOKUP(D5,'6月'!D:L,9,0) -> 2.725 | K5: =VLOOKUP(D5,'6月'!D:M,10,0) -> 1.75 | L5: =VLOOKUP(D5,'6月'!D:N,11,0) -> 5 | M5: =VLOOKUP(D5,'6月'!D:O,12,0) -> 3.57 | N5: =VLOOKUP(D5,'6月'!D:P,13,0) -> 2.725 | O5: =I5/$E5*$F5 -> 3.9 | P5: =J5/$E5*$F5 -> 2.725 | Q5: =K5/$E5*$F5 -> 1.75 | R5: =L5/$E5*$F5 -> 5 | S5: =M5/$E5*$F5 -> 3.57 | T5: =N5/$E5*$F5 -> 2.725
D6: 智家工程师满意度（4分） | E6: 4 | F6: 4 | I6: =VLOOKUP(D6,'6月'!D:K,8,0) -> 3.12 | J6: =VLOOKUP(D6,'6月'!D:L,9,0) -> 1.4 | K6: =VLOOKUP(D6,'6月'!D:M,10,0) -> 1.4 | L6: =VLOOKUP(D6,'6月'!D:N,11,0) -> 4 | M6: =VLOOKUP(D6,'6月'!D:O,12,0) -> 3.12 | N6: =VLOOKUP(D6,'6月'!D:P,13,0) -> 1.4 | O6: =I6/$E6*$F6 -> 3.12 | P6: =J6/$E6*$F6 -> 1.4 | Q6: =K6/$E6*$F6 -> 1.4 | R6: =L6/$E6*$F6 -> 4 | S6: =M6/$E6*$F6 -> 3.12 | T6: =N6/$E6*$F6 -> 1.4
B7: 网运成本管控 | C7: 13 | D7: 网络相关成本占收比（9分） | E7: 9 | F7: 2 | G7: （1）指标定义 网络相关成本占收比=（网络相关成本÷联网通信及其他业务收入）×100% 网络相关成本占收比预算目标=（网络相关成本预算÷联网通信及其他业务收入预算）×100% 网络相关成本占收比预算完成率=网络相关成本占收比÷网络相关成本占收比预算目标，焦作目标值：15.01% | H7: （2）计分办法 ①网络相关成本占收比预算完成率≤100%，得满分。 ②网络相关成本占收比预算完成率>100%，每超1PP扣本项分数的10%，线性得分。 （3）评价规则及数据来源 该指标按年度考核，数据来源于财务系统全成本报表。 | I7: =VLOOKUP(D7,'6月'!D:K,8,0) -> 9 | J7: =VLOOKUP(D7,'6月'!D:L,9,0) -> 9 | K7: =VLOOKUP(D7,'6月'!D:M,10,0) -> 9 | L7: =VLOOKUP(D7,'6月'!D:N,11,0) -> 9 | M7: =VLOOKUP(D7,'6月'!D:O,12,0) -> 9 | N7: =VLOOKUP(D7,'6月'!D:P,13,0) -> 9 | O7: =I7/$E7*$F7 -> 2 | P7: =J7/$E7*$F7 -> 2 | Q7: =K7/$E7*$F7 -> 2 | R7: =L7/$E7*$F7 -> 2 | S7: =M7/$E7*$F7 -> 2 | T7: =N7/$E7*$F7 -> 2
D8: 铁塔差异管控（3分） | E8: 2 | F8: 3 | G8: （1）指标定义 该指标由2025年列账差异率、2025年月列账金额波动率、2023年至2025年订单退租及降配证据固化率三项指标构成。 ①2025年列账差异率=1-联通列账金额÷铁塔列账金额× 100%,增量与存量一体化管控。 ②2025年月列账金额波动幅度 =[（当月列账金额 - 上月列账金额）÷上月列账金额]×100%，考核剔除正常波动值 ③2023年至2025年订单退租及降配证据固化率=通过审核的举证材料÷2023 年 1 月 1 日至 2025 年 12 月 31 日期间造成铁塔出账差异的订单退租及降配的举证材料× 100%。 | H8: （2）计分办法 ①2026年列账差异管控≤5%，分值2分。 2026年年度列账差异管控≤5%不扣分，超过5%得0分。 ②单站租赁费≤ 1605元，分值1分。 单站租赁费≤ 1605元%不扣分，每超过 1元扣 0.1 分。 | I8: =VLOOKUP(D8,'6月'!D:K,8,0) -> 3 | J8: =VLOOKUP(D8,'6月'!D:L,9,0) -> 3 | K8: =VLOOKUP(D8,'6月'!D:M,10,0) -> 3 | L8: =VLOOKUP(D8,'6月'!D:N,11,0) -> 3 | M8: =VLOOKUP(D8,'6月'!D:O,12,0) -> 3 | N8: =VLOOKUP(D8,'6月'!D:P,13,0) -> 3 | O8: =I8/$E8*$F8 -> 4.5 | P8: =J8/$E8*$F8 -> 4.5 | Q8: =K8/$E8*$F8 -> 4.5 | R8: =L8/$E8*$F8 -> 4.5 | S8: =M8/$E8*$F8 -> 4.5 | T8: =N8/$E8*$F8 -> 4.5
D9: 能耗成本（5分） | E9: 5 | F9: 5 | G9: （1）指标定义 能耗成本预算完成率=（全成本科目能耗成本实际完成值/能耗成本预算目标值）×100% 能耗成本压降=各单位压降目标完成值 焦作目标值：网络线能耗成本预算目标2739万元，其他能耗成本预算目标503.6万元 能耗成本压降100万 | H9: （2）计分办法 ①能耗成本预算完成率（4分）=网络线能耗成本完成率（3分）+其他能耗成本完成率（1分） ②实际完成值≤预算目标值得满分。 ③实际完成值每超预算目标值1pp扣本项分数的10%，线性扣分，本指标分值扣完为止。 ④各单位实际完成目标压降比例线性得分，线性排名 （3）评价规则及数据来源 各单位实际完成率 | I9: =VLOOKUP(D9,'6月'!D:K,8,0) -> 5 | J9: =VLOOKUP(D9,'6月'!D:L,9,0) -> 5 | K9: =VLOOKUP(D9,'6月'!D:M,10,0) -> 5 | L9: =VLOOKUP(D9,'6月'!D:N,11,0) -> 5 | M9: =VLOOKUP(D9,'6月'!D:O,12,0) -> 5 | N9: =VLOOKUP(D9,'6月'!D:P,13,0) -> 5 | O9: =I9/$E9*$F9 -> 5 | P9: =J9/$E9*$F9 -> 5 | Q9: =K9/$E9*$F9 -> 5 | R9: =L9/$E9*$F9 -> 5 | S9: =M9/$E9*$F9 -> 5 | T9: =N9/$E9*$F9 -> 5
A10: 运营提升 ( 55%) | B10: 网络质量提升专项行动-工匠行动 | C10: 10 | D10: 工匠行动年度得分排名（10分） | E10: 10 | F10: 10 | G10: 1、指标定义 该指标指工匠行动年度积分排名。 | H10: （2）计分办法 工匠行动年度积分第1名的市分公司对应得满分10分。 排名2至18名的市分公司，根据其工匠行动年度积分占第一名市分公司积分的比例，同比计算本项分数。 计算公式为：本项分数 = 10 ×（分公司积分 / 第一名分公司积分） （3）评价规则及数据来源 该指标按年度考核，数据来源以省公司统一发布的工匠行动年度积分统计结果为准。 | I10: =VLOOKUP(D10,'6月'!D:K,8,0) -> 10 | J10: =VLOOKUP(D10,'6月'!D:L,9,0) -> 10 | K10: =VLOOKUP(D10,'6月'!D:M,10,0) -> 10 | L10: =VLOOKUP(D10,'6月'!D:N,11,0) -> 10 | M10: =VLOOKUP(D10,'6月'!D:O,12,0) -> 10 | N10: =VLOOKUP(D10,'6月'!D:P,13,0) -> 10 | O10: =I10/$E10*$F10 -> 10 | P10: =J10/$E10*$F10 -> 10 | Q10: =K10/$E10*$F10 -> 10 | R10: =L10/$E10*$F10 -> 10 | S10: =M10/$E10*$F10 -> 10 | T10: =N10/$E10*$F10 -> 10
B11: 网络质量提升专项行动-极简网络 | C11: 10 | D11: 极简网络年度综合评价（10分） | E11: 10 | F11: 4 | G11: 1、指标定义 该指标由持续建强基础架构、常态化推进接入段光缆优化整治、提升整体运营能力三项指标构成。 （1）持续建强基础架构=2026年计划完成全量锚点机房实现网络天眼八大能力+锚点机房油机新建13台； （2）常态化推进接入段光缆优化整治=投资307万，按照各单位序时任务分解完成序时进度。 （3）提升整体运营能力=完成103个架构节点机房数字化建模+284机房数字化验收。 | H11: 2、计分办法 （1）持续建强基础架构年底前完成100%，得2.9分，每低于1pp扣基本分*1%，扣完本项分值为止。 （2）常态化推进接入段光缆优化整治月度目标完成100%，得4分，每低于1pp扣基本分*1%，扣完本项分值为止。 （3）提升整体运营能力月度目标完成100%，得3分，每低于1pp扣基本分*1%，扣完本项分值为止 （4）集团公司每采纳极简网络一个案例，对应市公司加0.1分。 （5）极简网络总体得分不超过10分。 | I11: =VLOOKUP(D11,'6月'!D:K,8,0) -> 10 | J11: =VLOOKUP(D11,'6月'!D:L,9,0) -> 10 | K11: =VLOOKUP(D11,'6月'!D:M,10,0) -> 10 | L11: =VLOOKUP(D11,'6月'!D:N,11,0) -> 10 | M11: =VLOOKUP(D11,'6月'!D:O,12,0) -> 10 | N11: =VLOOKUP(D11,'6月'!D:P,13,0) -> 10 | O11: =I11/$E11*$F11 -> 4 | P11: =J11/$E11*$F11 -> 4 | Q11: =K11/$E11*$F11 -> 4 | R11: =L11/$E11*$F11 -> 4 | S11: =M11/$E11*$F11 -> 4 | T11: =N11/$E11*$F11 -> 4
B12: 网络质量提升专项行动-网络运营安全深化年 | C12: 6 | D12: 同路由整治处理（2分） | E12: 2 | F12: 2 | G12: 1、指标定义 （1）所有达到S级机房完成纯物理双路由整改（包括同井，同馈窗）； （2）所有上联业务完成不同环路整改。 | H12: 2、计分办法 （1）全量双路由整改年底前完成100%，得50%得分，每低于1pp扣0.2，扣完本项分值为止。 （2）上联业务不同环路整改二季度完成100%，得50%得分，每低于1pp扣0.2，扣完本项分值为止。 | I12: =VLOOKUP(D12,'6月'!D:K,8,0) -> 2 | J12: =VLOOKUP(D12,'6月'!D:L,9,0) -> 2 | K12: =VLOOKUP(D12,'6月'!D:M,10,0) -> 2 | L12: =VLOOKUP(D12,'6月'!D:N,11,0) -> 2 | M12: =VLOOKUP(D12,'6月'!D:O,12,0) -> 2 | N12: =VLOOKUP(D12,'6月'!D:P,13,0) -> 2 | O12: =I12/$E12*$F12 -> 2 | P12: =J12/$E12*$F12 -> 2 | Q12: =K12/$E12*$F12 -> 2 | R12: =L12/$E12*$F12 -> 2 | S12: =M12/$E12*$F12 -> 2 | T12: =N12/$E12*$F12 -> 2
D13: 网络安全事件（4分） | E13: 4 | F13: 4 | G13: （1）指标定义 该指标由账号管理安全事件、违规动网操作、违规数据配置、违规分光事件四项指标构成。 | H13: （2）计分办法 ①发生账号管理安全事件扣1分，最多扣1分。 ②发现一起违规动网操作扣0.2分，因违规动网操作导致发生较大及以上网络故障或网络安全责任事件扣1分，最多扣1分。 ③发现一起违规数据配置扣0.2分，因违规数据配置导致发生较大及以上网络故障或网络安全责任事件扣1分，最多扣1分。 ④发生违规分光事件扣1分，因违规分光导致发生较大及以上网络故障或网络安全责任事件扣4分，最多扣4分。 ⑤被上级单位通报的加倍扣分，最多扣4分。 （3）评价规则及数据来源 该指标按年度进行考核，数据来源于上级单位/省公司通报。 | I13: =VLOOKUP(D13,'6月'!D:K,8,0) -> 4 | J13: =VLOOKUP(D13,'6月'!D:L,9,0) -> 4 | K13: =VLOOKUP(D13,'6月'!D:M,10,0) -> 4 | L13: =VLOOKUP(D13,'6月'!D:N,11,0) -> 4 | M13: =VLOOKUP(D13,'6月'!D:O,12,0) -> 4 | N13: =VLOOKUP(D13,'6月'!D:P,13,0) -> 4 | O13: =I13/$E13*$F13 -> 4 | P13: =J13/$E13*$F13 -> 4 | Q13: =K13/$E13*$F13 -> 4 | R13: =L13/$E13*$F13 -> 4 | S13: =M13/$E13*$F13 -> 4 | T13: =N13/$E13*$F13 -> 4
B14: 网络服务提升专项行动-移网质量提升 | C14: 11 | D14: 重点场景提升（3分） | E14: 3 | F14: 3 | G14: （1）指标定义 该指标由非住宅达标率、住宅专项（A类+千户覆盖达标率）、住宅专项（新建住宅覆盖达标率）、地下空间完成情况（上报及时率及地下空间建设目标完成率）四项指标组成。 | H14: （2）计分办法 ①非住宅场景达标100%（1分） 非住宅达标率100%满分，<85%得0分，中间线性记分。 ②A类+千户场景达标率100%（1分） A类+千户移网覆盖达标率100%满分，<85%得0分，中间线性记分。 ③新建住宅场景达标率100%（0.5分） 新建住宅移网覆盖达标率100%满分，<85%得0分，中间线性记分。 ④工信部覆盖达标率100%（0.5分） 工信部覆盖达标率100%满分，<85%得0分，中间线性记分。 区县建设任务得分取自本地市建设任务得分，每月低于当月建设目标值1%，则线性扣分0.1分，扣完为止。 （3）评价规则及数据来源 该指标按年度进行考核，数据来源于集团评估通报及省内自评。 | I14: =VLOOKUP(D14,'6月'!D:K,8,0) -> 1.88 | J14: =VLOOKUP(D14,'6月'!D:L,9,0) -> 2.86 | K14: =VLOOKUP(D14,'6月'!D:M,10,0) -> 2.8 | L14: =VLOOKUP(D14,'6月'!D:N,11,0) -> 2.91 | M14: =VLOOKUP(D14,'6月'!D:O,12,0) -> 2.16 | N14: =VLOOKUP(D14,'6月'!D:P,13,0) -> 3 | O14: =I14/$E14*$F14 -> 1.88 | P14: =J14/$E14*$F14 -> 2.86 | Q14: =K14/$E14*$F14 -> 2.8 | R14: =L14/$E14*$F14 -> 2.91 | S14: =M14/$E14*$F14 -> 2.16 | T14: =N14/$E14*$F14 -> 3
D15: 移网问题栅格改善（3分） | E15: 3 | F15: 3 | G15: （1）指标定义 该指标指年度移网问题栅格改善率。 年度移网问题栅格改善率=12期拍照问题栅格改善数/本年12期拍照问题栅格数。 ①移网问题栅格判定标准：逐月对月移网投诉量≥3或移网服请不满≥4的问题栅格拍照，认定移网问题栅格。 ②问题栅格改善标准：移网问题栅格设定1个月的改善期，省分闭环解决网络问题，并保持改善效果；改善期后，如连续2个月投诉量＜3或移网服请不满＜4，视为问题栅格改善。 | H15: （2）计分办法 ①问题栅格改善率达标目标值80%。 ②达标得满分3分，不达标0分。 （3）评价规则及数据来源 该指标按月跟踪通报，以全年累计改善率计算年度得分。数据来源于集团公司客户服务运营平台。 | I15: =VLOOKUP(D15,'6月'!D:K,8,0) -> 3 | J15: =VLOOKUP(D15,'6月'!D:L,9,0) -> 3 | K15: =VLOOKUP(D15,'6月'!D:M,10,0) -> 3 | L15: =VLOOKUP(D15,'6月'!D:N,11,0) -> 3 | M15: =VLOOKUP(D15,'6月'!D:O,12,0) -> 0 | N15: =VLOOKUP(D15,'6月'!D:P,13,0) -> 3 | O15: =I15/$E15*$F15 -> 3 | P15: =J15/$E15*$F15 -> 3 | Q15: =K15/$E15*$F15 -> 3 | R15: =L15/$E15*$F15 -> 3 | S15: =M15/$E15*$F15 -> 0 | T15: =N15/$E15*$F15 -> 3
D16: 业务感知提升（4分） | E16: 4 | F16: 2 | G16: （1）指标定义 该指标由语音业务良好体验率、语音业务感知掉话率、4G数据业务卡顿小区比例、5G数据业务卡顿小区比例、同站重复故障比例五项指标构成。 ①语音业务良好体验率=语音业务良好体验次数/语音业务次数 a.语音业务良好体验次数 = 同时满足“接得通”、“接得快”、“听得清”、“不掉话”的业务次数 ，被叫为移动、电信、固网时，语音业务良好体验只需满足“接得通”、“听得清”、“不掉话”； ②语音业务感知掉话率=语音业务感知掉话次数/语音业务次数 针对双方都是联通移网用户的语音通话进行评价。如果二者之间上一次通话时长超过2秒钟，并且上一次通话结束后40秒之内又发起呼叫（上一次通话的主被叫发起呼叫皆可），排除第二次呼叫拒接、运营商测试以及短号码等因素之后，将上一次通话定义为语音业务感知掉话； ③4G数据业务卡顿小区比例=4G数据业务卡顿小区/4G小区总数 ④5G数据业务卡顿小区比例=5G数据业务卡顿小区/5G小区总数 下行时延大于 200ms 概率超过 10%，记为卡顿小区。(电信 800M小区不纳入考核；联通 900M 小区时延大于 200ms 概率超过 20%，记为卡顿小区。) ⑤同站重复故障比例=（当月同站重复故障数量+集码BBU原因造成的重复故障+连续两个月同站重复故障）/当月物理站址故障总量*100%。 | H16: （2）计分办法 ①语音业务良好体验率≥97%（2分） 达标得满分，＜96%得0分，[96%,97%)线性打分。 ②数据业务体验良好率≥97%（2分） 达标得满分，＜96%得0分，[96%,97%)线性打分。 | I16: =VLOOKUP(D16,'6月'!D:K,8,0) -> 0.92 | J16: =VLOOKUP(D16,'6月'!D:L,9,0) -> 2.69 | K16: =VLOOKUP(D16,'6月'!D:M,10,0) -> 0.96 | L16: =VLOOKUP(D16,'6月'!D:N,11,0) -> 2.66 | M16: =VLOOKUP(D16,'6月'!D:O,12,0) -> 2.16 | N16: =VLOOKUP(D16,'6月'!D:P,13,0) -> 2.5 | O16: =I16/$E16*$F16 -> 0.46 | P16: =J16/$E16*$F16 -> 1.345 | Q16: =K16/$E16*$F16 -> 0.48 | R16: =L16/$E16*$F16 -> 1.33 | S16: =M16/$E16*$F16 -> 1.08 | T16: =N16/$E16*$F16 -> 1.25
D17: 移网资源利用率（1分） | E17: 1 | F17: 1 | G17: （1）指标定义 该指标指综合考虑3.5GHz、2.1GHz、900M无线资源利用率情况，并基于各频段下行频率资源和小区数进行加权统计。 ①移动资源利用率=[7*3.5GHz宏站小区规模*3.5GHz宏站小区无线资源利用率+2*2.1GHz（20M带宽）宏站小区规模*2.1GHz（20M带宽）宏站小区无线资源利用率+4*2.1GHz（40M带宽）宏站小区规模*2.1GHz（40M带宽）宏站小区无线资源利用率+900MHz宏站小区规模*900MHz宏站小区资源利用率]/(7*3.5GHz宏站小区规模+2*2.1GHz（20M带宽）宏站小区规模+4*2.1GHz（40M带宽）宏站小区规模+900MHz宏站小区规模)。 ②5G中频宏站小区无线资源利用率=Σ(小区自忙时下行PDSCH信道占用PRB个数*相应PRB调用层数）/Σ(小区自忙时的每空分流下行PDSCH信道可用PRB个数*小区下行时域平均最大调度层数(剔除0值))/K值，其中5G中频包括3.5GHz、2.1GHz（20M带宽）、2.1GHz（40M带宽），Σ表示所有5G中频宏站按小区求和，K值取典型值50%。 ③900MHz宏站小区资源利用率=（L900下行PRB占用数/L900下行PRB可用数）*L900小区数量占比+（NR900下行PRB占用数/NR900下行PRB可用数）*NR900小区数量占比。 | H17: （2）计分办法 目标无线资源利用率≥30%。 ①完成值大于等于达标值得满分； ②完成值低于基准值（2026年1月指标）不得分； ③完成值相较于2026年1月基准值未提升，得满分的80%； ④完成值低于达标值，但实现提升的，按照完成情况在满分与满分的80%之间线性计分。 （3）评价规则及数据来源 该指标按年度进行考核，数据来源于集团通报。 | I17: =VLOOKUP(D17,'6月'!D:K,8,0) -> 0.8 | J17: =VLOOKUP(D17,'6月'!D:L,9,0) -> 1 | K17: =VLOOKUP(D17,'6月'!D:M,10,0) -> 1 | L17: =VLOOKUP(D17,'6月'!D:N,11,0) -> 1 | M17: =VLOOKUP(D17,'6月'!D:O,12,0) -> 1 | N17: =VLOOKUP(D17,'6月'!D:P,13,0) -> 1 | O17: =I17/$E17*$F17 -> 0.8 | P17: =J17/$E17*$F17 -> 1 | Q17: =K17/$E17*$F17 -> 1 | R17: =L17/$E17*$F17 -> 1 | S17: =M17/$E17*$F17 -> 1 | T17: =N17/$E17*$F17 -> 1
B18: 网络服务提升专项行动-智家网络服务提升 | C18: 13 | D18: 交付质量提升（4分） | E18: 4 | F18: 4 | G18: （1）指标定义 该指标由装维动作合格率、456标准修障达标率两项指标构成。 ①装维动作合格率=1-不满足装维要求的装维动作总量/装维总量 ②456标准修障达标率=（16点前生单且在456时限内修复的工单数+16点后生单且在第二天12:00前修复的工单数）/（本周期内的竣工单+所选周期结束时间的在途工单） | H18: （2）计分办法 ①各项设定达标值和基准值，高于达标值得满分、低于基准值不得分，在达标值和基准值之间的线性计分。 ②装维动作合格率（2分），达标值≥98.5%，基准值≥95%。 ③456标准修障达标率（2分），达标值≥80%，基准值≥70%。 a.若修机当日好≥90%，456标准修障达标率评价值取实际完成值； b.若修机当日好＜90%，456标准修障达标率评价值=456标准修障达标率实际完成值*修机当日好率。 （3）评价规则及数据来源 该指标按月评价计分，以月指标得分的均值计算年度得分。数据来源于宽带网络数字化运营平台、经营分析系统。 | I18: =VLOOKUP(D18,'6月'!D:K,8,0) -> 3.1948052 | J18: =VLOOKUP(D18,'6月'!D:L,9,0) -> 3.3216342 | K18: =VLOOKUP(D18,'6月'!D:M,10,0) -> 2 | L18: =VLOOKUP(D18,'6月'!D:N,11,0) -> 4 | M18: =VLOOKUP(D18,'6月'!D:O,12,0) -> 2.9618574 | N18: =VLOOKUP(D18,'6月'!D:P,13,0) -> 4 | O18: =I18/$E18*$F18 -> 3.1948052 | P18: =J18/$E18*$F18 -> 3.3216342 | Q18: =K18/$E18*$F18 -> 2 | R18: =L18/$E18*$F18 -> 4 | S18: =M18/$E18*$F18 -> 2.9618574 | T18: =N18/$E18*$F18 -> 4
D19: 宽带资源效能提升（3分） | E19: 3 | F19: 2 | G19: （1）指标定义 该指标由全量宽带端口利用率、存量资源准确率、新装宽带一次核配准确率三项指标构成。 ①全量宽带端口利用率=所有接入方式下宽带占用端口数/（FTTH端口总量+PON_LAN数据端口总量）。 ②新增号线资源规范率=四项标准都通过的新增末梢分光器/全量的新增末梢分光器 ③新装宽带一次核配准确率=一次性完成资源核配并成功施工报竣的装移机工单数量/新装宽带工单总量*100％。 | H19: （2）计分办法 各项设定基准值和达标值，高于达标值得满分、低于基准值不得分，在达标值和基准值之间的线性计分。 ①全量宽带端口利用率（1分），分地市确定设置基准值、达标值。各地市目标如下：57.92%。 完成值≥达标值得1分；完成值低于基准值得0.8分；完成值低于达标值，但高于基准值的，按照提升值在1分与0.8分之间线性计分。 ②新增号线资源规范率（1分）、新装宽带一次核配准确率（1分），基准值为≥82%，达标值为≥92%。 a.完成值≥92%得1分，完成值＜82%不得分，82%-92%之间线性打分。 b.新装宽带一次核配准确率具备打分条件之前，按照存量资源准确率打分；具备打分条件之后，按照两个子指标分别打分。 （3）评价规则及数据来源 ①全量宽带端口利用率取12月数据进行评价； ②新增号线资源规范率Q1≥70%；Q2≥90%；Q3≥95%；Q4≥95%,未完成序时进度扣1分 ③数据来源于号线资源分析系统、宽带网络数字化运营平台。 | I19: =VLOOKUP(D19,'6月'!D:K,8,0) -> 3 | J19: =VLOOKUP(D19,'6月'!D:L,9,0) -> 3 | K19: =VLOOKUP(D19,'6月'!D:M,10,0) -> 3 | L19: =VLOOKUP(D19,'6月'!D:N,11,0) -> 3 | M19: =VLOOKUP(D19,'6月'!D:O,12,0) -> 3 | N19: =VLOOKUP(D19,'6月'!D:P,13,0) -> 3 | O19: =I19/$E19*$F19 -> 2 | P19: =J19/$E19*$F19 -> 2 | Q19: =K19/$E19*$F19 -> 2 | R19: =L19/$E19*$F19 -> 2 | S19: =M19/$E19*$F19 -> 2 | T19: =N19/$E19*$F19 -> 2
D20: 客户感知提升（6分） | E20: 3 | F20: 3 | G20: （1）指标定义 该指标由PON口在服率、PON口质差率、全量宽带故障率（10010+96480）、宽带投诉率、网络服务感知综合评价四项指标构成。 其中网络服务综合感知评价=响应率*10%+解决率*40%+满意率*50%，包括投诉、故障和咨办工单。 | H20: （2）计分办法 ①各项设定达标值和基准值，高于达标值得满分、低于基准值不得分，在达标值和基准值之间的线性计分。 ②PON口在服率（1分），达标值≥99.5%，基准值≥99%。若当月出现规模故障，按次评价，每发生一次当月扣0.5分。 ③PON口质差率（2分），达标值≤2.0%，基准值≤2.24%。若当月出现规模故障，按次评价，每发生一次当月扣0.5分。 （3）评价规则及数据来源 该指标按月评价计分，以月度得分均值计算年度得分。数据来源于宽带网络数字化运营平台、中国联通客服运营平台、经营分析系统。 | I20: 3 | J20: 3 | K20: 3 | L20: 3 | M20: 3 | N20: 3 | O20: =I20/$E20*$F20 -> 3 | P20: =J20/$E20*$F20 -> 3 | Q20: =K20/$E20*$F20 -> 3 | R20: =L20/$E20*$F20 -> 3 | S20: =M20/$E20*$F20 -> 3 | T20: =N20/$E20*$F20 -> 3
E21: 3 | F21: 3 | H21: （2）计分办法 ①各项设定达标值和基准值，高于达标值得满分、低于基准值不得分，在达标值和基准值之间的线性计分。 ③全量宽带故障率（1分），达标值≤90件/万户，基准值≤110件/万户。 ④宽带投诉率（1分），达标值≤1.3件/万户，基准值≤4件/万户。 ⑤网络服务综合感知评价（1分），达标值≥95%，基准值≥92%。 a.若96480服务满意率≥95%，网络服务综合感知评价取实际完成值； b.若96480服务满意率＜95%，网络服务综合感知评价=网络服务综合感知评价实际完成值*96480服务满意率。 （3）评价规则及数据来源 该指标按月评价计分，以月度得分均值计算年度得分。数据来源于宽带网络数字化运营平台、中国联通客服运营平台、经营分析系统。 | I21: 2.791236 | J21: 3 | K21: 2.9167634 | L21: 3 | M21: 2.6568151 | N21: 3 | O21: =I21/$E21*$F21 -> 2.791236 | P21: =J21/$E21*$F21 -> 3 | Q21: =K21/$E21*$F21 -> 2.9167634 | R21: =L21/$E21*$F21 -> 3 | S21: =M21/$E21*$F21 -> 2.6568151 | T21: =N21/$E21*$F21 -> 3
B22: 网络服务提升专项行动-政企双线网络服务提升 | C22: 5 | D22: 政企双线交付及时率（1分） | E22: 1 | F22: 1 | G22: （1）指标定义 该指标由全量宽带端口利用率、社会地址住宅小区全里末梢分光器准确率、新装宽带一次核配准确率三项、指标构成。 ①全量宽带端口利用率=所有接入方式下宽带占用端口数/（FTTH端口总量+PON_LAN数据端口总量）。 ②新装宽带一次核配准确率=一次性完成资源核配并成功施工报竣的装移机工单数量/新装宽带工单总量*100％。 | H22: （2）计分办法 各项设定基准值和达标值，高于达标值得满分、低于基准值不得分，在达标值和基准值之间的线性计分。 ①全量宽带端口利用率（1分），分地市确定设置基准值、达标值。各地市目标如下：57.92%。 完成值≥达标值得1分；完成值低于基准值得0.8分；完成值低于达标值，但高于基准值的，按照提升值在1分与0.8分之间线性计分。 ②社会地址住宅小区全里末梢分光器准确率：4月之后保持成功率≥92%，每低目标值1个百分点，减0.5分 b.新装宽带一次核配准确率具备打分条件之前，按照存量资源准确率打分；具备打分条件之后，按照两个子指标分别打分。 （3）评价规则及数据来源 ①全量宽带端口利用率取12月数据进行评价； ②新增号线资源规范率Q1≥70%；Q2≥90%；Q3≥95%；Q4≥95%,未完成序时进度扣1分 ③数据来源于号线资源分析系统、宽带网络数字化运营平台。 | I22: =VLOOKUP(D22,'6月'!D:K,8,0) -> 1 | J22: =VLOOKUP(D22,'6月'!D:L,9,0) -> 1 | K22: =VLOOKUP(D22,'6月'!D:M,10,0) -> 1 | L22: =VLOOKUP(D22,'6月'!D:N,11,0) -> 1 | M22: =VLOOKUP(D22,'6月'!D:O,12,0) -> 1 | N22: =VLOOKUP(D22,'6月'!D:P,13,0) -> 1 | O22: =I22/$E22*$F22 -> 1 | P22: =J22/$E22*$F22 -> 1 | Q22: =K22/$E22*$F22 -> 1 | R22: =L22/$E22*$F22 -> 1 | S22: =M22/$E22*$F22 -> 1 | T22: =N22/$E22*$F22 -> 1
D23: 政企双线故障管控（2分） | E23: 2 | F23: 2 | G23: （1）指标定义 该指标由政企双线故障4小时处理及时率、政企双线监控告警返单及时率两项指标构成。 国内跨域双线故障率=（政企客户跨域双线故障次数÷政企客户跨域双线电路总数）×100%。 | H23: （2）计分办法 ①政企双线故障4小时处理及时率=1-（不及时处理政企双线故障次数÷应处理政企双线故障总次数）×100%，满分1分，基本分0.8分，低于98%不得分，98%-100%之间线性得分，线性部分得分=0.2*（完成值-98%）/(100%-98%)； ②政企双线监控告警返单及时率=1-处理超时的政企双线告警工单数/政企双线告警工单总数，满分1分； ③国内跨域双线故障率，目标值：≤1.0%，满分1分。 （3）评价规则及数据来源 该指标按月评价计分，以月度得分均值计算年度得分。数据来源于OSS2.0业务故障2.0、智慧派单系统。 | I23: =VLOOKUP(D23,'6月'!D:K,8,0) -> 2 | J23: =VLOOKUP(D23,'6月'!D:L,9,0) -> 2 | K23: =VLOOKUP(D23,'6月'!D:M,10,0) -> 2 | L23: =VLOOKUP(D23,'6月'!D:N,11,0) -> 2 | M23: =VLOOKUP(D23,'6月'!D:O,12,0) -> 2 | N23: =VLOOKUP(D23,'6月'!D:P,13,0) -> 2 | O23: =I23/$E23*$F23 -> 2 | P23: =J23/$E23*$F23 -> 2 | Q23: =K23/$E23*$F23 -> 2 | R23: =L23/$E23*$F23 -> 2 | S23: =M23/$E23*$F23 -> 2 | T23: =N23/$E23*$F23 -> 2
D24: 政企双线资源治理（2分） | E24: 2 | F24: 3 | G24: （1）指标定义 该指标由政企双线电路拼接、政企双线末端光设施绑定标准地址完整率、B-O-O数据一致性稽核、资源一次自动核配成功率、互联网专线自动开通成功率构成。 互联网专线自动开通成功率=全程自动核配成功率*数据自动制作成功率 | H24: （2）计分办法 ①政企电路拼接完成率：4月之后保持成功率≥98.5%，每低目标值1个百分点，减0.5分 ②政企双线末端光设施绑定标准地址完整率=绑定的政企电路数/全量政企电路数，4月之后保持成功率≥98.5%，每低目标值1个百分点，减0.5分 ③ 双线BOO数据一致率=BO数据一致率*0.4+OO数据一致率*0.6 1、BO数据一致率=BO数量一致率*0.3+BO状态一致率*0.3+BO速率一致率*0.3+BO类型一致率*0.1 注：“BO数量、状态、速率、类型一致率”指B域系统与O域网络资源系统数据稽核一致率。 2、OO数据一致率=OO数量一致率*0.4+OO状态一致率*0.3+OO速率一致率*0.3。目标值96%，完成目标得满分，每低目标值1个百分点，减0.3分. ④资源一次自动核配成功率：4月≥10%；5月≥20%；6月≥30%；7月≥40%；8月≥50%；9月≥60%；10月≥70%；11月以后≥80%，每低目标值1个百分点，减0.3分 ⑤互联网专线自动开通成功率 4月-6月基准值20%、达标值30%，≥30%得满分，<20%不得分，中间线性得分 7月-9月基准值30%、达标值60%，≥60%得满分，<30%不得分，中间线性得分 10月-12月基准值60%、达标值90%，≥90%得满分，<60%不得分，中间线性得分 （3）评价规则及数据来源 该指标按月评价计分，以月度得分均值计算年度得分。数据来源于网络资源中心、B域客户订单、O域网络资源中心和O域网管系统、云网格系统。 | I24: =VLOOKUP(D24,'6月'!D:K,8,0) -> 2 | J24: =VLOOKUP(D24,'6月'!D:L,9,0) -> 2 | K24: =VLOOKUP(D24,'6月'!D:M,10,0) -> 2 | L24: =VLOOKUP(D24,'6月'!D:N,11,0) -> 2 | M24: =VLOOKUP(D24,'6月'!D:O,12,0) -> 2 | N24: =VLOOKUP(D24,'6月'!D:P,13,0) -> 2 | O24: =I24/$E24*$F24 -> 3 | P24: =J24/$E24*$F24 -> 3 | Q24: =K24/$E24*$F24 -> 3 | R24: =L24/$E24*$F24 -> 3 | S24: =M24/$E24*$F24 -> 3 | T24: =N24/$E24*$F24 -> 3
A25: 端网业协同 | B25: 端网业协同 | C25: 10 | D25: 5G登网率 | E25: 3 | F25: 3 | G25: （1）指标定义 5G签约用户5G终端登网 | H25: （2）计分办法 月度清单制推进5G终端SA开关打开，按月度目标完成率在60%到100%间线性得分，低于60%不得分 | I25: =VLOOKUP(D25,'6月'!D:K,8,0) -> / | J25: =VLOOKUP(D25,'6月'!D:L,9,0) -> / | K25: =VLOOKUP(D25,'6月'!D:M,10,0) -> / | L25: =VLOOKUP(D25,'6月'!D:N,11,0) -> / | M25: =VLOOKUP(D25,'6月'!D:O,12,0) -> / | N25: =VLOOKUP(D25,'6月'!D:P,13,0) -> / | O25: / | P25: / | Q25: / | R25: / | S25: / | T25: /
D26: 千兆化 | E26: 7 | F26: 7 | G26: （1）指标定义 该指标由路由器压降目标完成率、低速通道整治完成率、终端匹配套餐升级整治完成率组成构成。 | H26: （2）计分办法 按时序进度完成率进行考核，达标不扣分，不达标线性扣分。 | I26: =VLOOKUP(D26,'6月'!D:K,8,0) -> 0.2835 | J26: =VLOOKUP(D26,'6月'!D:L,9,0) -> 7 | K26: =VLOOKUP(D26,'6月'!D:M,10,0) -> 2.422 | L26: =VLOOKUP(D26,'6月'!D:N,11,0) -> 7 | M26: =VLOOKUP(D26,'6月'!D:O,12,0) -> 5.5545 | N26: =VLOOKUP(D26,'6月'!D:P,13,0) -> 7 | O26: =I26/$E26*$F26 -> 0.2835 | P26: =J26/$E26*$F26 -> 7 | Q26: =K26/$E26*$F26 -> 2.422 | R26: =L26/$E26*$F26 -> 7 | S26: =M26/$E26*$F26 -> 5.5545 | T26: =N26/$E26*$F26 -> 7
A27: 公司KPI保障 | B27: 公司KPI保障 | C27: -3 | D27: 科技创新（2分） | E27: 2 | F27: 2 | G27: （1）指标定义 科技创新研发投入贡献 | H27: ①科技创新研发项目无项目扣1分 ②每月工时未及时录入扣1分 | I27: =VLOOKUP(D27,'6月'!D:K,8,0) -> 0 | J27: =VLOOKUP(D27,'6月'!D:L,9,0) -> 0 | K27: =VLOOKUP(D27,'6月'!D:M,10,0) -> 0 | L27: =VLOOKUP(D27,'6月'!D:N,11,0) -> 0 | M27: =VLOOKUP(D27,'6月'!D:O,12,0) -> 0 | N27: =VLOOKUP(D27,'6月'!D:P,13,0) -> 0 | O27: =I27/$E27*$F27 -> 0 | P27: =J27/$E27*$F27 -> 0 | Q27: =K27/$E27*$F27 -> 0 | R27: =L27/$E27*$F27 -> 0 | S27: =M27/$E27*$F27 -> 0 | T27: =N27/$E27*$F27 -> 0
D28: 反诈治理 | E28: -5 | F28: -5 | G28: (1)指标定义 该指标由涉案号码治理、政企业务涉案治理、信安工单综合评价率、“内鬼”事件四项指标组成。 | H28: （2）计分方法 指标A:涉案号码治理(1.5分)：1、A1涉案电话号码（含手机号码和固话号码）数量同比下降，得0.5分，同比上升60%得0分，在此之间线性得分。2、当地行业移动电话号码涉案占比偏差率（简称“A2”）：A2≤0.9得1分，A2>1.5不得分，在此之间线性计分。 指标B:政企业务涉案治理（2分）：行业短信端口年度涉案量≤15，得1分；政企固话业务年度涉案量≤2，得1分，或涉案量系统内占比低于用户数占比得1分，高于10个百分点得0分，在此之间线性得分。 指标C：信安工单综合评价率（1分）：2026年信安工单综合评价率全年月均达到92.6%及以上的，得1分；90%-92.6%线性得分，低于90%不得分； 指标D：“内鬼”事件（0.5分） 市场发展、业务合作、IT支撑、渠道管理、网络运营及建设等领域，2026年没有新发生的“内鬼”事件，得满分；发生内鬼事件，视情况扣0.2-0.5分。 | I28: 0 | J28: 0 | K28: =VLOOKUP(D28,'6月'!D:M,10,0) -> -0.8 | L28: 0 | M28: 0 | N28: =VLOOKUP(D28,'6月'!D:P,13,0) -> -0.8 | O28: =I28/$E28*$F28 -> 0 | P28: =J28/$E28*$F28 -> 0 | Q28: =K28/$E28*$F28 -> -0.8 | R28: =L28/$E28*$F28 -> 0 | S28: =M28/$E28*$F28 -> 0 | T28: =N28/$E28*$F28 -> -0.8
D29: 县公司KPI排名 | E29: / | F29: 10 | H29: 按每月财务部公布各单位KPI得分，最终得分=实际得分/10，最高得10分 | O29: 10 | P29: 10 | Q29: 10 | R29: 10 | S29: 10 | T29: 10
A30: 约束事项 | B30: 约束事项 | C30: ±5 | D30: 正负项激励 | E30: ±5 | F30: ±5 | O30: 0 | P30: 0 | Q30: 0 | R30: 0 | S30: 0 | T30: 0
A31: 总分 | F31: =SUM(F2:F30) -> 100 | O31: =SUM(O2:O30) -> 85.529541 | P31: =SUM(P2:P30) -> 91.751634 | Q31: =SUM(Q2:Q30) -> 82.968763 | R31: =SUM(R2:R30) -> 96.94 | S31: =SUM(S2:S30) -> 88.403172 | T31: =SUM(T2:T30) -> 91.675
O32: =O31/97*100 -> 88.174785 | P32: =P31/97*100 -> 94.589314 | Q32: =Q31/97*100 -> 85.534808 | R32: =R31/97*100 -> 99.938144 | S32: =S31/97*100 -> 91.137291 | T32: =T31/97*100 -> 94.510309

Sheet 区
A1: 考核维度 | C1: 考核分值 | D1: 考核指标 | E1: 本地分值 | F1: 区公司拟定分值 | G1: 指标定义 | H1: 考核细则 | I1: 山阳 | J1: 解放 | K1: 马村 | L1: 中站 | M1: 山阳 | N1: 解放 | O1: 马村 | P1: 中站
A2: 核心功能（45%） | B2: 网络运营 | C2: 12 | D2: 故障管控（10分） | E2: 10 | F2: 10 | G2: （1）故障次数管控（8分） ①指标定义 根据网络规模分地市设定S级故障发生次数管控目标，S1/S2/S3/S4级故障分别按照10次、5次、2次、1次折合故障次数。焦作目标值21。 | H2: （1）故障次数管控（8分） ①计分办法 次数低于管控目标不扣分，高于管控目标，每超出管控目标1次扣0.05分，扣完为止。 ②评价规则及数据来源 该指标按年度考核，数据来源于云网格系统。 （2）S级故障（2分） ①计分办法 a.发生S1级故障，每次扣罚0.1分;发生S2级故障，每次扣罚0.05分，扣完为止。 b.出现因人为操作不当、非割接时段动网、隐患未排查发现、隐患未及时整改引起故障的，乘系数1.2进行扣分。 ②评价规则及数据来源 该指标按年度考核，数据来源于云网格系统。 | I2: 9.3 | J2: 9.3 | K2: 9.3 | L2: 9.3 | M2: =I2/$E2*$F2 -> 9.3 | N2: =J2/$E2*$F2 -> 9.3 | O2: =K2/$E2*$F2 -> 9.3 | P2: =L2/$E2*$F2 -> 9.3
D3: 能力提升（2分） | E3: 2 | F3: 2 | G3: （1）指标定义 内外部认证：，指从事线路、动力、无线、ip等专业等相关专业维护工作所涉及集团运维工程师、智网工程师、网络创新工程师以及与专业相关的外部认证。 六级人才：是指参与省公司网络线战略人才或技术人员7级工认证 | H3: （2）计分办法 内外部认证占比=内外部认证人员数量/各单位专业人员总数；内部认证目标完成率100%。 ①系统内部认证完成率，每低0.1%，扣1分； ②外部认证占比网络中心、交付考核目标30%，区县分公司考核目标15%，每低0.1%，扣1分； ③六级人才占比=六级人员数量/各单位专业人员总数要求10%以上，每低0.1%，扣1分 ④科创能力认证通过率，以科创岗位族人数为依据，考核目标60%，每低0.1%，扣1分 ⑤战略人才竞聘，各单位每新增或保持年审通过，加0.5分。 （3）评价规则及数据来源， 该指标为年度指标，数据来源省公司通报数据。 | I3: 2 | J3: 2 | K3: 2 | L3: 2 | M3: =I3/$E3*$F3 -> 2 | N3: =J3/$E3*$F3 -> 2 | O3: =K3/$E3*$F3 -> 2 | P3: =L3/$E3*$F3 -> 2
B4: 网络服务提升 | C4: 13 | D4: 移动网络满意度（5分） | E4: 5 | F4: 4 | G4: 1、指标定义 该指标由移动网络满意度、宽带网络满意度、智家工程师满意度三项指标构成。 | H4: 计分办法： （1）若满意度有全部明细能够区分各单位得分，按照省公司计分办法计算得分； （2）否则按照低评用户占比计算得分： ①根据各单位语音及上网具体打分情况计算低分占比情况； ②得分1分的系数为1，2-6分系数为0.5，7-8系数为0.2； ③计算1-8分得分的占比情况后计算最终得分（满分10分）； 1.当占比≤10%；得分=10−0.09×低评用户占比×100； 2.当占比介于10%和20%之间；得分=10−0.11×低评用户占比×100； 3.当占比≥20%；得分=10−0.13×低评用户占比×100； （3）最终移动网络满意度、宽带网络满意度折算为5分、智家工程师满意度折算为4分。 | I4: 2.5 | J4: 2.5 | K4: 2.5 | L4: 2.5 | M4: =I4/$E4*$F4 -> 2 | N4: =J4/$E4*$F4 -> 2 | O4: =K4/$E4*$F4 -> 2 | P4: =L4/$E4*$F4 -> 2
D5: 宽固网络满意度（4分） | E5: 4 | F5: 8 | I5: 3.9 | J5: 3.9 | K5: 1.75 | L5: 3.9 | M5: =I5/$E5*$F5 -> 7.8 | N5: =J5/$E5*$F5 -> 7.8 | O5: =K5/$E5*$F5 -> 3.5 | P5: =L5/$E5*$F5 -> 7.8
D6: 智家工程师满意度（4分） | E6: 4 | F6: 8 | I6: 3.12 | J6: 4 | K6: 4 | L6: 3.12 | M6: =I6/$E6*$F6 -> 6.24 | N6: =J6/$E6*$F6 -> 8 | O6: =K6/$E6*$F6 -> 8 | P6: =L6/$E6*$F6 -> 6.24
B7: 网运成本管控 | C7: 13 | D7: 网络相关成本占收比（6分） | E7: 6 | F7: 2 | G7: （1）指标定义 网络相关成本占收比=（网络相关成本÷联网通信及其他业务收入）×100% 网络相关成本占收比预算目标=（网络相关成本预算÷联网通信及其他业务收入预算）×100% 网络相关成本占收比预算完成率=网络相关成本占收比÷网络相关成本占收比预算目标，焦作目标值：15.01% | H7: （2）计分办法 ①网络相关成本占收比预算完成率≤100%，得满分。 ②网络相关成本占收比预算完成率>100%，每超1PP扣本项分数的10%，线性得分。 （3）评价规则及数据来源 该指标按年度考核，数据来源于财务系统全成本报表。 | I7: 9 | J7: 9 | K7: 9 | L7: 9 | M7: =I7/$E7*$F7 -> 3 | N7: =J7/$E7*$F7 -> 3 | O7: =K7/$E7*$F7 -> 3 | P7: =L7/$E7*$F7 -> 3
